Workbook

Sheet دليل الاستخدام
B1: 📘 دليل استخدام شيت إهلاك الأصول - المطاعم (مترابط بالكامل)
B3: 📝 نظرة عامة
B5: 🔗 آلية الربط بين الأوراق
B6: 1. سجل الأصول | C6: ← المصدر الوحيد للبيانات — أضف/عدّل/احذف الأصول هنا فقط
B7: 2. جدول الإهلاك | C7: ← يقرأ تلقائياً من 'سجل الأصول' — لا تعدل يدوياً
B8: 3. الملخص والتقارير | C8: ← يقرأ من 'سجل الأصول' و'جدول الإهلاك' — لا تعدل يدوياً
B9: 4. سجل التعديلات | C9: ← سجل يدوي لتتبع التغييرات (للمراجعة الداخلية)
B10: 5. القيمة الدفترية عبر الزمن | C10: ← يحسب تلقائياً تطور القيمة الدفترية شهرياً
B12: ⚠️ تعليمات مهمة
B13: • | C13: لا تعدل أي صيغ في 'جدول الإهلاك' أو 'الملخص' — هي مترابطة تلقائياً
B14: • | C14: أضف الأصول في 'سجل الأصول' فقط، وسيتم حساب الإهلاك تلقائياً
B15: • | C15: لحذف أصل: امسح الصف في 'سجل الأصول' أو غيّر الحالة إلى 'مهلك'
B16: • | C16: سجل أي تعديل في 'سجل التعديلات' للحفاظ على أثر المراجعة
B17: • | C17: القيمة الدفترية تُحسب ديناميكياً بناءً على تاريخ الاستخدام
B19: 📱 التوافق

Sheet سجل الأصول
B2: 📋 سجل أصول المطعم — المصدر الرئيسي (Master Data)
B3: ⚠️ أضف/عدّل الأصول هنا فقط — جميع الأوراق الأخرى مترابطة مع هذا الجدول
B5: # | C5: اسم الأصل | D5: الفئة | E5: التكلفة (العملة المحددة) | F5: القيمة المتبقية | G5: المبلغ القابل للإهلاك | H5: تاريخ الشراء | I5: تاريخ الاستخدام | J5: العمر الإنتاجي | K5: طريقة الإهلاك | L5: معدل الإهلاك % | M5: القيمة الدفترية | N5: الحالة
B6: 1 | C6: فرن بيتزا صناعي | D6: معدات المطبخ | E6: 60000 | F6: 5000 | G6: =IF(C6="","",MAX(0,E6-F6)) -> 55000 | H6: 45306 | I6: 45323 | J6: 8 | K6: القسط الثابت | L6: =IF(OR(C6="",J6<=0),"",ROUND(100/J6,2)) -> 12.5 | M6: =IF(C6="","",IF(N6="مهلك",F6,MAX(F6,IF(I6>TODAY(),E6,IF(K6="القسط الثابت",E6-G6*MIN(MAX(0,(YEAR(TODAY())-YEAR(I6))*12+MONTH(TODAY())-MONTH(I6)),J6*12)/(J6*12),IF(K6="القسط المتناقص",E6*(1-L6/100)^MIN(MAX(0,YEAR(TODAY())-YEAR(I6)),J6),IF(K6="وحدات الإنتاج",E6-G6*MIN(100,L6*MAX(0,YEAR(TODAY())-YEAR(I6)))/100,E6))))))) -> 42239.583 | N6: نشط
B7: 2 | C7: ثلاجة عرض مشروبات | D7: معدات المطبخ | E7: 18000 | F7: 2000 | G7: =IF(C7="","",MAX(0,E7-F7)) -> 16000 | H7: 45311 | I7: 45323 | J7: 6 | K7: القسط الثابت | L7: =IF(OR(C7="",J7<=0),"",ROUND(100/J7,2)) -> 16.67 | M7: =IF(C7="","",IF(N7="مهلك",F7,MAX(F7,IF(I7>TODAY(),E7,IF(K7="القسط الثابت",E7-G7*MIN(MAX(0,(YEAR(TODAY())-YEAR(I7))*12+MONTH(TODAY())-MONTH(I7)),J7*12)/(J7*12),IF(K7="القسط المتناقص",E7*(1-L7/100)^MIN(MAX(0,YEAR(TODAY())-YEAR(I7)),J7),IF(K7="وحدات الإنتاج",E7-G7*MIN(100,L7*MAX(0,YEAR(TODAY())-YEAR(I7)))/100,E7))))))) -> 11111.111 | N7: نشط
B8: 3 | C8: غسالة صحون صناعية | D8: معدات المطبخ | E8: 25000 | F8: 3000 | G8: =IF(C8="","",MAX(0,E8-F8)) -> 22000 | H8: 45332 | I8: 45352 | J8: 7 | K8: القسط الثابت | L8: =IF(OR(C8="",J8<=0),"",ROUND(100/J8,2)) -> 14.29 | M8: =IF(C8="","",IF(N8="مهلك",F8,MAX(F8,IF(I8>TODAY(),E8,IF(K8="القسط الثابت",E8-G8*MIN(MAX(0,(YEAR(TODAY())-YEAR(I8))*12+MONTH(TODAY())-MONTH(I8)),J8*12)/(J8*12),IF(K8="القسط المتناقص",E8*(1-L8/100)^MIN(MAX(0,YEAR(TODAY())-YEAR(I8)),J8),IF(K8="وحدات الإنتاج",E8-G8*MIN(100,L8*MAX(0,YEAR(TODAY())-YEAR(I8)))/100,E8))))))) -> 17142.857 | N8: نشط
B9: 4 | C9: شواية غاز مفتوحة | D9: معدات المطبخ | E9: 32000 | F9: 4000 | G9: =IF(C9="","",MAX(0,E9-F9)) -> 28000 | H9: 45356 | I9: 45366 | J9: 10 | K9: القسط الثابت | L9: =IF(OR(C9="",J9<=0),"",ROUND(100/J9,2)) -> 10 | M9: =IF(C9="","",IF(N9="مهلك",F9,MAX(F9,IF(I9>TODAY(),E9,IF(K9="القسط الثابت",E9-G9*MIN(MAX(0,(YEAR(TODAY())-YEAR(I9))*12+MONTH(TODAY())-MONTH(I9)),J9*12)/(J9*12),IF(K9="القسط المتناقص",E9*(1-L9/100)^MIN(MAX(0,YEAR(TODAY())-YEAR(I9)),J9),IF(K9="وحدات الإنتاج",E9-G9*MIN(100,L9*MAX(0,YEAR(TODAY())-YEAR(I9)))/100,E9))))))) -> 25000 | N9: نشط
B10: 5 | C10: جهاز POS (نقاط البيع) | D10: أنظمة تقنية | E10: 8000 | F10: 500 | G10: =IF(C10="","",MAX(0,E10-F10)) -> 7500 | H10: 45292 | I10: 45296 | J10: 4 | K10: القسط المتناقص | L10: =IF(OR(C10="",J10<=0),"",ROUND(100/J10,2)) -> 25 | M10: =IF(C10="","",IF(N10="مهلك",F10,MAX(F10,IF(I10>TODAY(),E10,IF(K10="القسط الثابت",E10-G10*MIN(MAX(0,(YEAR(TODAY())-YEAR(I10))*12+MONTH(TODAY())-MONTH(I10)),J10*12)/(J10*12),IF(K10="القسط المتناقص",E10*(1-L10/100)^MIN(MAX(0,YEAR(TODAY())-YEAR(I10)),J10),IF(K10="وحدات الإنتاج",E10-G10*MIN(100,L10*MAX(0,YEAR(TODAY())-YEAR(I10)))/100,E10))))))) -> 4500 | N10: نشط
B11: 6 | C11: نظام كاميرات مراقبة | D11: أنظمة تقنية | E11: 15000 | F11: 1000 | G11: =IF(C11="","",MAX(0,E11-F11)) -> 14000 | H11: 45301 | I11: 45306 | J11: 5 | K11: القسط المتناقص | L11: =IF(OR(C11="",J11<=0),"",ROUND(100/J11,2)) -> 20 | M11: =IF(C11="","",IF(N11="مهلك",F11,MAX(F11,IF(I11>TODAY(),E11,IF(K11="القسط الثابت",E11-G11*MIN(MAX(0,(YEAR(TODAY())-YEAR(I11))*12+MONTH(TODAY())-MONTH(I11)),J11*12)/(J11*12),IF(K11="القسط المتناقص",E11*(1-L11/100)^MIN(MAX(0,YEAR(TODAY())-YEAR(I11)),J11),IF(K11="وحدات الإنتاج",E11-G11*MIN(100,L11*MAX(0,YEAR(TODAY())-YEAR(I11)))/100,E11))))))) -> 9600 | N11: نشط
B12: 7 | C12: أثاث صالة الطعام | D12: أثاث وديكور | E12: 55000 | F12: 8000 | G12: =IF(C12="","",MAX(0,E12-F12)) -> 47000 | H12: 45292 | I12: 45323 | J12: 10 | K12: القسط الثابت | L12: =IF(OR(C12="",J12<=0),"",ROUND(100/J12,2)) -> 10 | M12: =IF(C12="","",IF(N12="مهلك",F12,MAX(F12,IF(I12>TODAY(),E12,IF(K12="القسط الثابت",E12-G12*MIN(MAX(0,(YEAR(TODAY())-YEAR(I12))*12+MONTH(TODAY())-MONTH(I12)),J12*12)/(J12*12),IF(K12="القسط المتناقص",E12*(1-L12/100)^MIN(MAX(0,YEAR(TODAY())-YEAR(I12)),J12),IF(K12="وحدات الإنتاج",E12-G12*MIN(100,L12*MAX(0,YEAR(TODAY())-YEAR(I12)))/100,E12))))))) -> 42858.333 | N12: نشط
B13: 8 | C13: إضاءة ديكور داخلي | D13: أثاث وديكور | E13: 22000 | F13: 3000 | G13: =IF(C13="","",MAX(0,E13-F13)) -> 19000 | H13: 45323 | I13: 45337 | J13: 8 | K13: القسط الثابت | L13: =IF(OR(C13="",J13<=0),"",ROUND(100/J13,2)) -> 12.5 | M13: =IF(C13="","",IF(N13="مهلك",F13,MAX(F13,IF(I13>TODAY(),E13,IF(K13="القسط الثابت",E13-G13*MIN(MAX(0,(YEAR(TODAY())-YEAR(I13))*12+MONTH(TODAY())-MONTH(I13)),J13*12)/(J13*12),IF(K13="القسط المتناقص",E13*(1-L13/100)^MIN(MAX(0,YEAR(TODAY())-YEAR(I13)),J13),IF(K13="وحدات الإنتاج",E13-G13*MIN(100,L13*MAX(0,YEAR(TODAY())-YEAR(I13)))/100,E13))))))) -> 15864.583 | N13: نشط
B14: 9 | C14: مكيفات مركزية HVAC | D14: تجهيزات | E14: 65000 | F14: 8000 | G14: =IF(C14="","",MAX(0,E14-F14)) -> 57000 | H14: 45292 | I14: 45323 | J14: 15 | K14: القسط الثابت | L14: =IF(OR(C14="",J14<=0),"",ROUND(100/J14,2)) -> 6.67 | M14: =IF(C14="","",IF(N14="مهلك",F14,MAX(F14,IF(I14>TODAY(),E14,IF(K14="القسط الثابت",E14-G14*MIN(MAX(0,(YEAR(TODAY())-YEAR(I14))*12+MONTH(TODAY())-MONTH(I14)),J14*12)/(J14*12),IF(K14="القسط المتناقص",E14*(1-L14/100)^MIN(MAX(0,YEAR(TODAY())-YEAR(I14)),J14),IF(K14="وحدات الإنتاج",E14-G14*MIN(100,L14*MAX(0,YEAR(TODAY())-YEAR(I14)))/100,E14))))))) -> 55183.333 | N14: نشط
B15: 10 | C15: سيارة توصيل طلبات | D15: مركبات | E15: 85000 | F15: 15000 | G15: =IF(C15="","",MAX(0,E15-F15)) -> 70000 | H15: 45311 | I15: 45323 | J15: 5 | K15: وحدات الإنتاج | L15: =IF(OR(C15="",J15<=0),"",ROUND(100/J15,2)) -> 20 | M15: =IF(C15="","",IF(N15="مهلك",F15,MAX(F15,IF(I15>TODAY(),E15,IF(K15="القسط الثابت",E15-G15*MIN(MAX(0,(YEAR(TODAY())-YEAR(I15))*12+MONTH(TODAY())-MONTH(I15)),J15*12)/(J15*12),IF(K15="القسط المتناقص",E15*(1-L15/100)^MIN(MAX(0,YEAR(TODAY())-YEAR(I15)),J15),IF(K15="وحدات الإنتاج",E15-G15*MIN(100,L15*MAX(0,YEAR(TODAY())-YEAR(I15)))/100,E15))))))) -> 57000 | N15: نشط
B16: 11 | C16: ماكينة قهوة احترافية | D16: معدات المطبخ | E16: 28000 | F16: 3500 | G16: =IF(C16="","",MAX(0,E16-F16)) -> 24500 | H16: 45352 | I16: 45361 | J16: 6 | K16: القسط الثابت | L16: =IF(OR(C16="",J16<=0),"",ROUND(100/J16,2)) -> 16.67 | M16: =IF(C16="","",IF(N16="مهلك",F16,MAX(F16,IF(I16>TODAY(),E16,IF(K16="القسط الثابت",E16-G16*MIN(MAX(0,(YEAR(TODAY())-YEAR(I16))*12+MONTH(TODAY())-MONTH(I16)),J16*12)/(J16*12),IF(K16="القسط المتناقص",E16*(1-L16/100)^MIN(MAX(0,YEAR(TODAY())-YEAR(I16)),J16),IF(K16="وحدات الإنتاج",E16-G16*MIN(100,L16*MAX(0,YEAR(TODAY())-YEAR(I16)))/100,E16))))))) -> 17791.667 | N16: نشط
B17: 12 | C17: طاولات وكراسي خارجية | D17: أثاث وديكور | E17: 18000 | F17: 2500 | G17: =IF(C17="","",MAX(0,E17-F17)) -> 15500 | H17: 45383 | I17: 45392 | J17: 7 | K17: القسط الثابت | L17: =IF(OR(C17="",J17<=0),"",ROUND(100/J17,2)) -> 14.29 | M17: =IF(C17="","",IF(N17="مهلك",F17,MAX(F17,IF(I17>TODAY(),E17,IF(K17="القسط الثابت",E17-G17*MIN(MAX(0,(YEAR(TODAY())-YEAR(I17))*12+MONTH(TODAY())-MONTH(I17)),J17*12)/(J17*12),IF(K17="القسط المتناقص",E17*(1-L17/100)^MIN(MAX(0,YEAR(TODAY())-YEAR(I17)),J17),IF(K17="وحدات الإنتاج",E17-G17*MIN(100,L17*MAX(0,YEAR(TODAY())-YEAR(I17)))/100,E17))))))) -> 12648.81 | N17: نشط
G18: =IF(C18="","",MAX(0,E18-F18)) | L18: =IF(OR(C18="",J18<=0),"",ROUND(100/J18,2)) | M18: =IF(C18="","",IF(N18="مهلك",F18,MAX(F18,IF(I18>TODAY(),E18,IF(K18="القسط الثابت",E18-G18*MIN(MAX(0,(YEAR(TODAY())-YEAR(I18))*12+MONTH(TODAY())-MONTH(I18)),J18*12)/(J18*12),IF(K18="القسط المتناقص",E18*(1-L18/100)^MIN(MAX(0,YEAR(TODAY())-YEAR(I18)),J18),IF(K18="وحدات الإنتاج",E18-G18*MIN(100,L18*MAX(0,YEAR(TODAY())-YEAR(I18)))/100,E18)))))))
G19: =IF(C19="","",MAX(0,E19-F19)) | L19: =IF(OR(C19="",J19<=0),"",ROUND(100/J19,2)) | M19: =IF(C19="","",IF(N19="مهلك",F19,MAX(F19,IF(I19>TODAY(),E19,IF(K19="القسط الثابت",E19-G19*MIN(MAX(0,(YEAR(TODAY())-YEAR(I19))*12+MONTH(TODAY())-MONTH(I19)),J19*12)/(J19*12),IF(K19="القسط المتناقص",E19*(1-L19/100)^MIN(MAX(0,YEAR(TODAY())-YEAR(I19)),J19),IF(K19="وحدات الإنتاج",E19-G19*MIN(100,L19*MAX(0,YEAR(TODAY())-YEAR(I19)))/100,E19)))))))
G20: =IF(C20="","",MAX(0,E20-F20)) | L20: =IF(OR(C20="",J20<=0),"",ROUND(100/J20,2)) | M20: =IF(C20="","",IF(N20="مهلك",F20,MAX(F20,IF(I20>TODAY(),E20,IF(K20="القسط الثابت",E20-G20*MIN(MAX(0,(YEAR(TODAY())-YEAR(I20))*12+MONTH(TODAY())-MONTH(I20)),J20*12)/(J20*12),IF(K20="القسط المتناقص",E20*(1-L20/100)^MIN(MAX(0,YEAR(TODAY())-YEAR(I20)),J20),IF(K20="وحدات الإنتاج",E20-G20*MIN(100,L20*MAX(0,YEAR(TODAY())-YEAR(I20)))/100,E20)))))))
G21: =IF(C21="","",MAX(0,E21-F21)) | L21: =IF(OR(C21="",J21<=0),"",ROUND(100/J21,2)) | M21: =IF(C21="","",IF(N21="مهلك",F21,MAX(F21,IF(I21>TODAY(),E21,IF(K21="القسط الثابت",E21-G21*MIN(MAX(0,(YEAR(TODAY())-YEAR(I21))*12+MONTH(TODAY())-MONTH(I21)),J21*12)/(J21*12),IF(K21="القسط المتناقص",E21*(1-L21/100)^MIN(MAX(0,YEAR(TODAY())-YEAR(I21)),J21),IF(K21="وحدات الإنتاج",E21-G21*MIN(100,L21*MAX(0,YEAR(TODAY())-YEAR(I21)))/100,E21)))))))
G22: =IF(C22="","",MAX(0,E22-F22)) | L22: =IF(OR(C22="",J22<=0),"",ROUND(100/J22,2)) | M22: =IF(C22="","",IF(N22="مهلك",F22,MAX(F22,IF(I22>TODAY(),E22,IF(K22="القسط الثابت",E22-G22*MIN(MAX(0,(YEAR(TODAY())-YEAR(I22))*12+MONTH(TODAY())-MONTH(I22)),J22*12)/(J22*12),IF(K22="القسط المتناقص",E22*(1-L22/100)^MIN(MAX(0,YEAR(TODAY())-YEAR(I22)),J22),IF(K22="وحدات الإنتاج",E22-G22*MIN(100,L22*MAX(0,YEAR(TODAY())-YEAR(I22)))/100,E22)))))))
G23: =IF(C23="","",MAX(0,E23-F23)) | L23: =IF(OR(C23="",J23<=0),"",ROUND(100/J23,2)) | M23: =IF(C23="","",IF(N23="مهلك",F23,MAX(F23,IF(I23>TODAY(),E23,IF(K23="القسط الثابت",E23-G23*MIN(MAX(0,(YEAR(TODAY())-YEAR(I23))*12+MONTH(TODAY())-MONTH(I23)),J23*12)/(J23*12),IF(K23="القسط المتناقص",E23*(1-L23/100)^MIN(MAX(0,YEAR(TODAY())-YEAR(I23)),J23),IF(K23="وحدات الإنتاج",E23-G23*MIN(100,L23*MAX(0,YEAR(TODAY())-YEAR(I23)))/100,E23)))))))
G24: =IF(C24="","",MAX(0,E24-F24)) | L24: =IF(OR(C24="",J24<=0),"",ROUND(100/J24,2)) | M24: =IF(C24="","",IF(N24="مهلك",F24,MAX(F24,IF(I24>TODAY(),E24,IF(K24="القسط الثابت",E24-G24*MIN(MAX(0,(YEAR(TODAY())-YEAR(I24))*12+MONTH(TODAY())-MONTH(I24)),J24*12)/(J24*12),IF(K24="القسط المتناقص",E24*(1-L24/100)^MIN(MAX(0,YEAR(TODAY())-YEAR(I24)),J24),IF(K24="وحدات الإنتاج",E24-G24*MIN(100,L24*MAX(0,YEAR(TODAY())-YEAR(I24)))/100,E24)))))))
G25: =IF(C25="","",MAX(0,E25-F25)) | L25: =IF(OR(C25="",J25<=0),"",ROUND(100/J25,2)) | M25: =IF(C25="","",IF(N25="مهلك",F25,MAX(F25,IF(I25>TODAY(),E25,IF(K25="القسط الثابت",E25-G25*MIN(MAX(0,(YEAR(TODAY())-YEAR(I25))*12+MONTH(TODAY())-MONTH(I25)),J25*12)/(J25*12),IF(K25="القسط المتناقص",E25*(1-L25/100)^MIN(MAX(0,YEAR(TODAY())-YEAR(I25)),J25),IF(K25="وحدات الإنتاج",E25-G25*MIN(100,L25*MAX(0,YEAR(TODAY())-YEAR(I25)))/100,E25)))))))
G26: =IF(C26="","",MAX(0,E26-F26)) | L26: =IF(OR(C26="",J26<=0),"",ROUND(100/J26,2)) | M26: =IF(C26="","",IF(N26="مهلك",F26,MAX(F26,IF(I26>TODAY(),E26,IF(K26="القسط الثابت",E26-G26*MIN(MAX(0,(YEAR(TODAY())-YEAR(I26))*12+MONTH(TODAY())-MONTH(I26)),J26*12)/(J26*12),IF(K26="القسط المتناقص",E26*(1-L26/100)^MIN(MAX(0,YEAR(TODAY())-YEAR(I26)),J26),IF(K26="وحدات الإنتاج",E26-G26*MIN(100,L26*MAX(0,YEAR(TODAY())-YEAR(I26)))/100,E26)))))))
G27: =IF(C27="","",MAX(0,E27-F27)) | L27: =IF(OR(C27="",J27<=0),"",ROUND(100/J27,2)) | M27: =IF(C27="","",IF(N27="مهلك",F27,MAX(F27,IF(I27>TODAY(),E27,IF(K27="القسط الثابت",E27-G27*MIN(MAX(0,(YEAR(TODAY())-YEAR(I27))*12+MONTH(TODAY())-MONTH(I27)),J27*12)/(J27*12),IF(K27="القسط المتناقص",E27*(1-L27/100)^MIN(MAX(0,YEAR(TODAY())-YEAR(I27)),J27),IF(K27="وحدات الإنتاج",E27-G27*MIN(100,L27*MAX(0,YEAR(TODAY())-YEAR(I27)))/100,E27)))))))
G28: =IF(C28="","",MAX(0,E28-F28)) | L28: =IF(OR(C28="",J28<=0),"",ROUND(100/J28,2)) | M28: =IF(C28="","",IF(N28="مهلك",F28,MAX(F28,IF(I28>TODAY(),E28,IF(K28="القسط الثابت",E28-G28*MIN(MAX(0,(YEAR(TODAY())-YEAR(I28))*12+MONTH(TODAY())-MONTH(I28)),J28*12)/(J28*12),IF(K28="القسط المتناقص",E28*(1-L28/100)^MIN(MAX(0,YEAR(TODAY())-YEAR(I28)),J28),IF(K28="وحدات الإنتاج",E28-G28*MIN(100,L28*MAX(0,YEAR(TODAY())-YEAR(I28)))/100,E28)))))))
G29: =IF(C29="","",MAX(0,E29-F29)) | L29: =IF(OR(C29="",J29<=0),"",ROUND(100/J29,2)) | M29: =IF(C29="","",IF(N29="مهلك",F29,MAX(F29,IF(I29>TODAY(),E29,IF(K29="القسط الثابت",E29-G29*MIN(MAX(0,(YEAR(TODAY())-YEAR(I29))*12+MONTH(TODAY())-MONTH(I29)),J29*12)/(J29*12),IF(K29="القسط المتناقص",E29*(1-L29/100)^MIN(MAX(0,YEAR(TODAY())-YEAR(I29)),J29),IF(K29="وحدات الإنتاج",E29-G29*MIN(100,L29*MAX(0,YEAR(TODAY())-YEAR(I29)))/100,E29)))))))
... G100: =IF(C100="","",MAX(0,E100-F100)) | L100: =IF(OR(C100="",J100<=0),"",ROUND(100/J100,2)) | M100: =IF(C100="","",IF(N100="مهلك",F100,MAX(F100,IF(I100>TODAY(),E100,IF(K100="القسط الثابت",E100-G100*MIN(MAX(0,(YEAR(TODAY())-YEAR(I100))*12+MONTH(TODAY())-MONTH(I100)),J100*12)/(J100*12),IF(K100="القسط المتناقص",E100*(1-L100/100)^MIN(MAX(0,YEAR(TODAY())-YEAR(I100)),J100),IF(K100="وحدات الإنتاج",E100-G100*MIN(100,L100*MAX(0,YEAR(TODAY())-YEAR(I100)))/100,E100)))))))
B101: الإجمالي | E101: =SUM(E6:E100) -> 431000 | F101: =SUM(F6:F100) -> 55500 | G101: =SUM(G6:G100) -> 375500 | M101: =SUM(M6:M100) -> 310940.28

Sheet جدول الإهلاك
B2: 📊 جدول الإهلاك — مترابط تلقائياً مع 'سجل الأصول'
B3: ⚠️ لا تعدل هذا الجدول يدوياً — جميع البيانات تُقرأ من 'سجل الأصول'
B5: # | C5: اسم الأصل | D5: التكلفة (العملة المحددة) | E5: القيمة المتبقية | F5: المبلغ القابل للإهلاك | G5: العمر (سنوات) | H5: طريقة الإهلاك | I5: معدل الإهلاك % | J5: الإهلاك الشهري | K5: الإهلاك السنوي | L5: الإهلاك التراكمي | M5: القيمة الدفترية
B6: =IF('سجل الأصول'!B6="","",'سجل الأصول'!B6) -> 1 | C6: =IF('سجل الأصول'!C6="","",'سجل الأصول'!C6) -> فرن بيتزا صناعي | D6: =IF(C6="","",'سجل الأصول'!E6) -> 60000 | E6: =IF(C6="","",'سجل الأصول'!F6) -> 5000 | F6: =IF(C6="","",'سجل الأصول'!G6) -> 55000 | G6: =IF(C6="","",'سجل الأصول'!J6) -> 8 | H6: =IF(C6="","",'سجل الأصول'!K6) -> القسط الثابت | I6: =IF(C6="","",'سجل الأصول'!L6) -> 12.5 | J6: =IF(OR(C6="",'سجل الأصول'!I6>TODAY(),G6<=0),0,IF(H6="القسط الثابت",F6/(G6*12),IF(H6="القسط المتناقص",D6*(I6/100)/12,IF(H6="وحدات الإنتاج",F6*I6/100/12,0)))) -> 572.91667 | K6: =IF(C6="",0,J6*12) -> 6875 | L6: =IF(OR(C6="",'سجل الأصول'!N6="مهلك"),0,MAX(0,D6-M6)) -> 17760.417 | M6: =IF(C6="","",'سجل الأصول'!M6) -> 42239.583
B7: =IF('سجل الأصول'!B7="","",'سجل الأصول'!B7) -> 2 | C7: =IF('سجل الأصول'!C7="","",'سجل الأصول'!C7) -> ثلاجة عرض مشروبات | D7: =IF(C7="","",'سجل الأصول'!E7) -> 18000 | E7: =IF(C7="","",'سجل الأصول'!F7) -> 2000 | F7: =IF(C7="","",'سجل الأصول'!G7) -> 16000 | G7: =IF(C7="","",'سجل الأصول'!J7) -> 6 | H7: =IF(C7="","",'سجل الأصول'!K7) -> القسط الثابت | I7: =IF(C7="","",'سجل الأصول'!L7) -> 16.67 | J7: =IF(OR(C7="",'سجل الأصول'!I7>TODAY(),G7<=0),0,IF(H7="القسط الثابت",F7/(G7*12),IF(H7="القسط المتناقص",D7*(I7/100)/12,IF(H7="وحدات الإنتاج",F7*I7/100/12,0)))) -> 222.22222 | K7: =IF(C7="",0,J7*12) -> 2666.6667 | L7: =IF(OR(C7="",'سجل الأصول'!N7="مهلك"),0,MAX(0,D7-M7)) -> 6888.8889 | M7: =IF(C7="","",'سجل الأصول'!M7) -> 11111.111
B8: =IF('سجل الأصول'!B8="","",'سجل الأصول'!B8) -> 3 | C8: =IF('سجل الأصول'!C8="","",'سجل الأصول'!C8) -> غسالة صحون صناعية | D8: =IF(C8="","",'سجل الأصول'!E8) -> 25000 | E8: =IF(C8="","",'سجل الأصول'!F8) -> 3000 | F8: =IF(C8="","",'سجل الأصول'!G8) -> 22000 | G8: =IF(C8="","",'سجل الأصول'!J8) -> 7 | H8: =IF(C8="","",'سجل الأصول'!K8) -> القسط الثابت | I8: =IF(C8="","",'سجل الأصول'!L8) -> 14.29 | J8: =IF(OR(C8="",'سجل الأصول'!I8>TODAY(),G8<=0),0,IF(H8="القسط الثابت",F8/(G8*12),IF(H8="القسط المتناقص",D8*(I8/100)/12,IF(H8="وحدات الإنتاج",F8*I8/100/12,0)))) -> 261.90476 | K8: =IF(C8="",0,J8*12) -> 3142.8571 | L8: =IF(OR(C8="",'سجل الأصول'!N8="مهلك"),0,MAX(0,D8-M8)) -> 7857.1429 | M8: =IF(C8="","",'سجل الأصول'!M8) -> 17142.857
B9: =IF('سجل الأصول'!B9="","",'سجل الأصول'!B9) -> 4 | C9: =IF('سجل الأصول'!C9="","",'سجل الأصول'!C9) -> شواية غاز مفتوحة | D9: =IF(C9="","",'سجل الأصول'!E9) -> 32000 | E9: =IF(C9="","",'سجل الأصول'!F9) -> 4000 | F9: =IF(C9="","",'سجل الأصول'!G9) -> 28000 | G9: =IF(C9="","",'سجل الأصول'!J9) -> 10 | H9: =IF(C9="","",'سجل الأصول'!K9) -> القسط الثابت | I9: =IF(C9="","",'سجل الأصول'!L9) -> 10 | J9: =IF(OR(C9="",'سجل الأصول'!I9>TODAY(),G9<=0),0,IF(H9="القسط الثابت",F9/(G9*12),IF(H9="القسط المتناقص",D9*(I9/100)/12,IF(H9="وحدات الإنتاج",F9*I9/100/12,0)))) -> 233.33333 | K9: =IF(C9="",0,J9*12) -> 2800 | L9: =IF(OR(C9="",'سجل الأصول'!N9="مهلك"),0,MAX(0,D9-M9)) -> 7000 | M9: =IF(C9="","",'سجل الأصول'!M9) -> 25000
B10: =IF('سجل الأصول'!B10="","",'سجل الأصول'!B10) -> 5 | C10: =IF('سجل الأصول'!C10="","",'سجل الأصول'!C10) -> جهاز POS (نقاط البيع) | D10: =IF(C10="","",'سجل الأصول'!E10) -> 8000 | E10: =IF(C10="","",'سجل الأصول'!F10) -> 500 | F10: =IF(C10="","",'سجل الأصول'!G10) -> 7500 | G10: =IF(C10="","",'سجل الأصول'!J10) -> 4 | H10: =IF(C10="","",'سجل الأصول'!K10) -> القسط المتناقص | I10: =IF(C10="","",'سجل الأصول'!L10) -> 25 | J10: =IF(OR(C10="",'سجل الأصول'!I10>TODAY(),G10<=0),0,IF(H10="القسط الثابت",F10/(G10*12),IF(H10="القسط المتناقص",D10*(I10/100)/12,IF(H10="وحدات الإنتاج",F10*I10/100/12,0)))) -> 166.66667 | K10: =IF(C10="",0,J10*12) -> 2000 | L10: =IF(OR(C10="",'سجل الأصول'!N10="مهلك"),0,MAX(0,D10-M10)) -> 3500 | M10: =IF(C10="","",'سجل الأصول'!M10) -> 4500
B11: =IF('سجل الأصول'!B11="","",'سجل الأصول'!B11) -> 6 | C11: =IF('سجل الأصول'!C11="","",'سجل الأصول'!C11) -> نظام كاميرات مراقبة | D11: =IF(C11="","",'سجل الأصول'!E11) -> 15000 | E11: =IF(C11="","",'سجل الأصول'!F11) -> 1000 | F11: =IF(C11="","",'سجل الأصول'!G11) -> 14000 | G11: =IF(C11="","",'سجل الأصول'!J11) -> 5 | H11: =IF(C11="","",'سجل الأصول'!K11) -> القسط المتناقص | I11: =IF(C11="","",'سجل الأصول'!L11) -> 20 | J11: =IF(OR(C11="",'سجل الأصول'!I11>TODAY(),G11<=0),0,IF(H11="القسط الثابت",F11/(G11*12),IF(H11="القسط المتناقص",D11*(I11/100)/12,IF(H11="وحدات الإنتاج",F11*I11/100/12,0)))) -> 250 | K11: =IF(C11="",0,J11*12) -> 3000 | L11: =IF(OR(C11="",'سجل الأصول'!N11="مهلك"),0,MAX(0,D11-M11)) -> 5400 | M11: =IF(C11="","",'سجل الأصول'!M11) -> 9600
B12: =IF('سجل الأصول'!B12="","",'سجل الأصول'!B12) -> 7 | C12: =IF('سجل الأصول'!C12="","",'سجل الأصول'!C12) -> أثاث صالة الطعام | D12: =IF(C12="","",'سجل الأصول'!E12) -> 55000 | E12: =IF(C12="","",'سجل الأصول'!F12) -> 8000 | F12: =IF(C12="","",'سجل الأصول'!G12) -> 47000 | G12: =IF(C12="","",'سجل الأصول'!J12) -> 10 | H12: =IF(C12="","",'سجل الأصول'!K12) -> القسط الثابت | I12: =IF(C12="","",'سجل الأصول'!L12) -> 10 | J12: =IF(OR(C12="",'سجل الأصول'!I12>TODAY(),G12<=0),0,IF(H12="القسط الثابت",F12/(G12*12),IF(H12="القسط المتناقص",D12*(I12/100)/12,IF(H12="وحدات الإنتاج",F12*I12/100/12,0)))) -> 391.66667 | K12: =IF(C12="",0,J12*12) -> 4700 | L12: =IF(OR(C12="",'سجل الأصول'!N12="مهلك"),0,MAX(0,D12-M12)) -> 12141.667 | M12: =IF(C12="","",'سجل الأصول'!M12) -> 42858.333
B13: =IF('سجل الأصول'!B13="","",'سجل الأصول'!B13) -> 8 | C13: =IF('سجل الأصول'!C13="","",'سجل الأصول'!C13) -> إضاءة ديكور داخلي | D13: =IF(C13="","",'سجل الأصول'!E13) -> 22000 | E13: =IF(C13="","",'سجل الأصول'!F13) -> 3000 | F13: =IF(C13="","",'سجل الأصول'!G13) -> 19000 | G13: =IF(C13="","",'سجل الأصول'!J13) -> 8 | H13: =IF(C13="","",'سجل الأصول'!K13) -> القسط الثابت | I13: =IF(C13="","",'سجل الأصول'!L13) -> 12.5 | J13: =IF(OR(C13="",'سجل الأصول'!I13>TODAY(),G13<=0),0,IF(H13="القسط الثابت",F13/(G13*12),IF(H13="القسط المتناقص",D13*(I13/100)/12,IF(H13="وحدات الإنتاج",F13*I13/100/12,0)))) -> 197.91667 | K13: =IF(C13="",0,J13*12) -> 2375 | L13: =IF(OR(C13="",'سجل الأصول'!N13="مهلك"),0,MAX(0,D13-M13)) -> 6135.4167 | M13: =IF(C13="","",'سجل الأصول'!M13) -> 15864.583
B14: =IF('سجل الأصول'!B14="","",'سجل الأصول'!B14) -> 9 | C14: =IF('سجل الأصول'!C14="","",'سجل الأصول'!C14) -> مكيفات مركزية HVAC | D14: =IF(C14="","",'سجل الأصول'!E14) -> 65000 | E14: =IF(C14="","",'سجل الأصول'!F14) -> 8000 | F14: =IF(C14="","",'سجل الأصول'!G14) -> 57000 | G14: =IF(C14="","",'سجل الأصول'!J14) -> 15 | H14: =IF(C14="","",'سجل الأصول'!K14) -> القسط الثابت | I14: =IF(C14="","",'سجل الأصول'!L14) -> 6.67 | J14: =IF(OR(C14="",'سجل الأصول'!I14>TODAY(),G14<=0),0,IF(H14="القسط الثابت",F14/(G14*12),IF(H14="القسط المتناقص",D14*(I14/100)/12,IF(H14="وحدات الإنتاج",F14*I14/100/12,0)))) -> 316.66667 | K14: =IF(C14="",0,J14*12) -> 3800 | L14: =IF(OR(C14="",'سجل الأصول'!N14="مهلك"),0,MAX(0,D14-M14)) -> 9816.6667 | M14: =IF(C14="","",'سجل الأصول'!M14) -> 55183.333
B15: =IF('سجل الأصول'!B15="","",'سجل الأصول'!B15) -> 10 | C15: =IF('سجل الأصول'!C15="","",'سجل الأصول'!C15) -> سيارة توصيل طلبات | D15: =IF(C15="","",'سجل الأصول'!E15) -> 85000 | E15: =IF(C15="","",'سجل الأصول'!F15) -> 15000 | F15: =IF(C15="","",'سجل الأصول'!G15) -> 70000 | G15: =IF(C15="","",'سجل الأصول'!J15) -> 5 | H15: =IF(C15="","",'سجل الأصول'!K15) -> وحدات الإنتاج | I15: =IF(C15="","",'سجل الأصول'!L15) -> 20 | J15: =IF(OR(C15="",'سجل الأصول'!I15>TODAY(),G15<=0),0,IF(H15="القسط الثابت",F15/(G15*12),IF(H15="القسط المتناقص",D15*(I15/100)/12,IF(H15="وحدات الإنتاج",F15*I15/100/12,0)))) -> 1166.6667 | K15: =IF(C15="",0,J15*12) -> 14000 | L15: =IF(OR(C15="",'سجل الأصول'!N15="مهلك"),0,MAX(0,D15-M15)) -> 28000 | M15: =IF(C15="","",'سجل الأصول'!M15) -> 57000
B16: =IF('سجل الأصول'!B16="","",'سجل الأصول'!B16) -> 11 | C16: =IF('سجل الأصول'!C16="","",'سجل الأصول'!C16) -> ماكينة قهوة احترافية | D16: =IF(C16="","",'سجل الأصول'!E16) -> 28000 | E16: =IF(C16="","",'سجل الأصول'!F16) -> 3500 | F16: =IF(C16="","",'سجل الأصول'!G16) -> 24500 | G16: =IF(C16="","",'سجل الأصول'!J16) -> 6 | H16: =IF(C16="","",'سجل الأصول'!K16) -> القسط الثابت | I16: =IF(C16="","",'سجل الأصول'!L16) -> 16.67 | J16: =IF(OR(C16="",'سجل الأصول'!I16>TODAY(),G16<=0),0,IF(H16="القسط الثابت",F16/(G16*12),IF(H16="القسط المتناقص",D16*(I16/100)/12,IF(H16="وحدات الإنتاج",F16*I16/100/12,0)))) -> 340.27778 | K16: =IF(C16="",0,J16*12) -> 4083.3333 | L16: =IF(OR(C16="",'سجل الأصول'!N16="مهلك"),0,MAX(0,D16-M16)) -> 10208.333 | M16: =IF(C16="","",'سجل الأصول'!M16) -> 17791.667
B17: =IF('سجل الأصول'!B17="","",'سجل الأصول'!B17) -> 12 | C17: =IF('سجل الأصول'!C17="","",'سجل الأصول'!C17) -> طاولات وكراسي خارجية | D17: =IF(C17="","",'سجل الأصول'!E17) -> 18000 | E17: =IF(C17="","",'سجل الأصول'!F17) -> 2500 | F17: =IF(C17="","",'سجل الأصول'!G17) -> 15500 | G17: =IF(C17="","",'سجل الأصول'!J17) -> 7 | H17: =IF(C17="","",'سجل الأصول'!K17) -> القسط الثابت | I17: =IF(C17="","",'سجل الأصول'!L17) -> 14.29 | J17: =IF(OR(C17="",'سجل الأصول'!I17>TODAY(),G17<=0),0,IF(H17="القسط الثابت",F17/(G17*12),IF(H17="القسط المتناقص",D17*(I17/100)/12,IF(H17="وحدات الإنتاج",F17*I17/100/12,0)))) -> 184.52381 | K17: =IF(C17="",0,J17*12) -> 2214.2857 | L17: =IF(OR(C17="",'سجل الأصول'!N17="مهلك"),0,MAX(0,D17-M17)) -> 5351.1905 | M17: =IF(C17="","",'سجل الأصول'!M17) -> 12648.81
... B100: =IF('سجل الأصول'!B100="","",'سجل الأصول'!B100) | C100: =IF('سجل الأصول'!C100="","",'سجل الأصول'!C100) | D100: =IF(C100="","",'سجل الأصول'!E100) | E100: =IF(C100="","",'سجل الأصول'!F100) | F100: =IF(C100="","",'سجل الأصول'!G100) | G100: =IF(C100="","",'سجل الأصول'!J100) | H100: =IF(C100="","",'سجل الأصول'!K100) | I100: =IF(C100="","",'سجل الأصول'!L100) | J100: =IF(OR(C100="",'سجل الأصول'!I100>TODAY(),G100<=0),0,IF(H100="القسط الثابت",F100/(G100*12),IF(H100="القسط المتناقص",D100*(I100/100)/12,IF(H100="وحدات الإنتاج",F100*I100/100/12,0)))) -> 0 | K100: =IF(C100="",0,J100*12) -> 0 | L100: =IF(OR(C100="",'سجل الأصول'!N100="مهلك"),0,MAX(0,D100-M100)) -> 0 | M100: =IF(C100="","",'سجل الأصول'!M100)
B101: الإجمالي | D101: =SUM(D6:D100) -> 431000 | E101: =SUM(E6:E100) -> 55500 | F101: =SUM(F6:F100) -> 375500 | G101: =SUM(G6:G100) -> 91 | I101: =SUM(I6:I100) -> 178.59 | J101: =SUM(J6:J100) -> 4304.7619 | K101: =SUM(K6:K100) -> 51657.143 | L101: =SUM(L6:L100) -> 120059.72 | M101: =SUM(M6:M100) -> 310940.28

Sheet الملخص والتقارير
B2: 📈 لوحة تحكم إهلاك الأصول — مترابطة تلقائياً
B3: ⚠️ لا تعدل هذا الجدول — جميع البيانات تُقرأ من 'سجل الأصول' و'جدول الإهلاك'
B4: العملة: ='إعدادات الإهلاك'!C29 | غيّرها من ورقة إعدادات الإهلاك
B5: 📊 مؤشرات الأداء الرئيسية (KPIs)
B7: 💰 إجمالي تكلفة الأصول | D7: 📉 الإهلاك التراكمي | F7: 📈 القيمة الدفترية الصافية
B8: =SUM('سجل الأصول'!E6:E100) -> 431000 | D8: =SUM('جدول الإهلاك'!L6:L100) -> 120059.72 | F8: =B8-D8 -> 310940.28
B10: 📅 الإهلاك الشهري | D10: 📆 الإهلاك السنوي | F10: 🔢 عدد الأصول النشطة
B11: =SUM('جدول الإهلاك'!J6:J100) -> 4304.7619 | D11: =SUM('جدول الإهلاك'!K6:K100) -> 51657.143 | F11: =COUNTIF('سجل الأصول'!N6:N100,"نشط") -> 12
B13: 📋 ملخص الأصول حسب الفئة — مترابط مع 'سجل الأصول'
B14: الفئة | C14: عدد الأصول | D14: التكلفة الإجمالية | E14: الإهلاك التراكمي | F14: القيمة الدفترية | G14: نسبة الإهلاك
B15: معدات المطبخ | C15: =COUNTIF('سجل الأصول'!D6:D100,B15) -> 5 | D15: =SUMIF('سجل الأصول'!D6:D100,B15,'سجل الأصول'!E6:E100) -> 163000 | E15: =SUMIF('سجل الأصول'!D6:D100,B15,'جدول الإهلاك'!L6:L100) -> 49714.782 | F15: =D15-E15 -> 113285.22 | G15: =IFERROR(E15/D15,0) -> 0.30499866
B16: أنظمة تقنية | C16: =COUNTIF('سجل الأصول'!D6:D100,B16) -> 2 | D16: =SUMIF('سجل الأصول'!D6:D100,B16,'سجل الأصول'!E6:E100) -> 23000 | E16: =SUMIF('سجل الأصول'!D6:D100,B16,'جدول الإهلاك'!L6:L100) -> 8900 | F16: =D16-E16 -> 14100 | G16: =IFERROR(E16/D16,0) -> 0.38695652
B17: أثاث وديكور | C17: =COUNTIF('سجل الأصول'!D6:D100,B17) -> 3 | D17: =SUMIF('سجل الأصول'!D6:D100,B17,'سجل الأصول'!E6:E100) -> 95000 | E17: =SUMIF('سجل الأصول'!D6:D100,B17,'جدول الإهلاك'!L6:L100) -> 23628.274 | F17: =D17-E17 -> 71371.726 | G17: =IFERROR(E17/D17,0) -> 0.24871867
B18: تجهيزات | C18: =COUNTIF('سجل الأصول'!D6:D100,B18) -> 1 | D18: =SUMIF('سجل الأصول'!D6:D100,B18,'سجل الأصول'!E6:E100) -> 65000 | E18: =SUMIF('سجل الأصول'!D6:D100,B18,'جدول الإهلاك'!L6:L100) -> 9816.6667 | F18: =D18-E18 -> 55183.333 | G18: =IFERROR(E18/D18,0) -> 0.15102564
B19: مركبات | C19: =COUNTIF('سجل الأصول'!D6:D100,B19) -> 1 | D19: =SUMIF('سجل الأصول'!D6:D100,B19,'سجل الأصول'!E6:E100) -> 85000 | E19: =SUMIF('سجل الأصول'!D6:D100,B19,'جدول الإهلاك'!L6:L100) -> 28000 | F19: =D19-E19 -> 57000 | G19: =IFERROR(E19/D19,0) -> 0.32941176
B20: الإجمالي | C20: =SUM(C15:C19) -> 12 | D20: =SUM(D15:D19) -> 431000 | E20: =SUM(E15:E19) -> 120059.72 | F20: =SUM(F15:F19) -> 310940.28 | G20: =SUM(G15:G19) -> 1.4211113
B22: ✅ قائمة التحقق من الامتثال لـ IAS 16
B23: # | C23: متطلب IAS 16 | D23: الحالة | E23: الملاحظات
B24: 1 | C24: الأصول مسجلة بالتكلفة (Cost Model) | D24: ✓ متوافق | E24: جميع الأصول مسجلة بالتكلفة الأصلية
B25: 2 | C25: الإهلاك يبدأ عند توفر الأصل للاستخدام | D25: ✓ متوافق | E25: تاريخ الاستخدام منفصل عن تاريخ الشراء
B26: 3 | C26: طريقة الإهلاك تعكس نمط الاستهلاك | D26: ✓ متوافق | E26: القسط الثابت للاستخدام المتساوي، المتناقص للتقنية
B27: 4 | C27: القيمة المتبقية محددة لكل أصل | D27: ✓ متوافق | E27: تم تقدير القيمة المتبقية بناءً على السوق
B28: 5 | C28: العمر الإنتاجي محدد لكل فئة | D28: ✓ متوافق | E28: العمر يعكس التجربة الصناعية
B29: 6 | C29: لا يوجد إهلاك قائم على الإيرادات | D29: ✓ متوافق | E29: ممنوع طبقاً للتعديل 2014
B30: 7 | C30: المكونات المهمة تُهملك منفصلة | D30: ✓ متوافق | E30: HVAC، المحركات، الأجزاء الرئيسية

Sheet سجل التعديلات
B2: 📝 سجل التعديلات — Audit Trail
B3: سجل يدوي لتتبع جميع التعديلات على أصول المطعم (للمراجعة الداخلية والخارجية)
B5: ⚠️ أضف صفاً جديداً في هذا الجدول عند كل تعديل في 'سجل الأصول' — هذا إلزامي للامتثال لـ IAS 16
B7: # | C7: التاريخ | D7: اسم الأصل | E7: نوع التعديل | F7: الحقل المعدل | G7: القيمة القديمة | H7: القيمة الجديدة | I7: الموظف / المراجع
B8: 1 | C8: 2024-01-15 | D8: فرن بيتزا صناعي | E8: إضافة أصل جديد | F8: — | G8: — | H8: تكلفة: 45,000 ريال | I8: أحمد المحاسب
B9: 2 | C9: 2024-03-01 | D9: غسالة صحون صناعية | E9: تعديل تاريخ الاستخدام | F9: تاريخ الاستخدام | G9: 2024-02-20 | H9: 2024-03-01 | I9: أحمد المحاسب
B10: 3 | C10: 2024-06-15 | D10: جهاز POS | E10: تعديل طريقة الإهلاك | F10: طريقة الإهلاك | G10: القسط الثابت | H10: القسط المتناقص | I10: المراجع الخارجي
B11: 4 | C11: 2024-08-01 | D11: سيارة توصيل طلبات | E11: تعديل القيمة المتبقية | F11: القيمة المتبقية | G11: 10,000 | H11: 15,000 | I11: أحمد المحاسب
B54: 📊 إحصائيات سجل التعديلات
B55: إجمالي التعديلات | C55: إضافات | D55: تعديلات | E55: حذف/مهلك | F55: آخر تعديل
B56: =COUNTA(C8:C51) -> 4 | C56: =COUNTIF(E8:E51,"إضافة أصل جديد") -> 1 | D56: =COUNTIFS(E8:E51,"<>إضافة أصل جديد",E8:E51,"<>حذف أصل",E8:E51,"<>تصنيف كمهلك") -> 43 | E56: =COUNTIF(E8:E51,"حذف أصل")+COUNTIF(E8:E51,"تصنيف كمهلك") -> 0 | F56: =MAX(C8:C51) -> 0

Sheet القيمة الدفترية عبر الزمن
B2: 📈 القيمة الدفترية عبر الزمن — Book Value Over Time
B3: ⚠️ هذا الجدول يُحسب تلقائياً — لا تعدل يدوياً — البيانات من 'سجل الأصول'
B5: الشهر / الفئة | C5: معدات المطبخ | D5: أنظمة تقنية | E5: أثاث وديكور | F5: تجهيزات | G5: مركبات | H5: الإجمالي
B6: يناير 2024 | C6: =SUMPRODUCT(('سجل الأصول'!$D$6:$D$100="معدات المطبخ")*('سجل الأصول'!$N$6:$N$100<>"مهلك")*('سجل الأصول'!$E$6:$E$100-IF('سجل الأصول'!$I$6:$I$100>DATE(2024+INT((ROW()-6)/12),MOD(ROW()-6,12)+2,0),0,IF('سجل الأصول'!$K$6:$K$100="القسط الثابت",'سجل الأصول'!$G$6:$G$100*MIN(MAX(0,(YEAR(DATE(2024+INT((ROW()-6)/12),MOD(ROW()-6,12)+2,0))-YEAR('سجل الأصول'!$I$6:$I$100))*12+MONTH(DATE(2024+INT((ROW()-6)/12),MOD(ROW()-6,12)+2,0))-MONTH('سجل الأصول'!$I$6:$I$100)),'سجل الأصول'!$J$6:$J$100*12)/('سجل الأصول'!$J$6:$J$100*12),IF('سجل الأصول'!$K$6:$K$100="القسط المتناقص",'سجل الأصول'!$E$6:$E$100*(1-(1-'سجل الأصول'!$L$6:$L$100/100)^MIN(MAX(0,YEAR(DATE(2024+INT((ROW()-6)/12),MOD(ROW()-6,12)+2,0))-YEAR('سجل الأصول'!$I$6:$I$100)),'سجل الأصول'!$J$6:$J$100)),IF('سجل الأصول'!$K$6:$K$100="وحدات الإنتاج",'سجل الأصول'!$G$6:$G$100*MIN(100,'سجل الأصول'!$L$6:$L$100*MAX(0,YEAR(DATE(2024+INT((ROW()-6)/12),MOD(ROW()-6,12)+2,0))-YEAR('سجل الأصول'!$I$6:$I$100)))/100,0)))))) -> 163000 | D6: =SUMPRODUCT(('سجل الأصول'!$D$6:$D$100="أنظمة تقنية")*('سجل الأصول'!$N$6:$N$100<>"مهلك")*('سجل الأصول'!$E$6:$E$100-IF('سجل الأصول'!$I$6:$I$100>DATE(2024+INT((ROW()-6)/12),MOD(ROW()-6,12)+2,0),0,IF('سجل الأصول'!$K$6:$K$100="القسط الثابت",'سجل الأصول'!$G$6:$G$100*MIN(MAX(0,(YEAR(DATE(2024+INT((ROW()-6)/12),MOD(ROW()-6,12)+2,0))-YEAR('سجل الأصول'!$I$6:$I$100))*12+MONTH(DATE(2024+INT((ROW()-6)/12),MOD(ROW()-6,12)+2,0))-MONTH('سجل الأصول'!$I$6:$I$100)),'سجل الأصول'!$J$6:$J$100*12)/('سجل الأصول'!$J$6:$J$100*12),IF('سجل الأصول'!$K$6:$K$100="القسط المتناقص",'سجل الأصول'!$E$6:$E$100*(1-(1-'سجل الأصول'!$L$6:$L$100/100)^MIN(MAX(0,YEAR(DATE(2024+INT((ROW()-6)/12),MOD(ROW()-6,12)+2,0))-YEAR('سجل الأصول'!$I$6:$I$100)),'سجل الأصول'!$J$6:$J$100)),IF('سجل الأصول'!$K$6:$K$100="وحدات الإنتاج",'سجل الأصول'!$G$6:$G$100*MIN(100,'سجل الأصول'!$L$6:$L$100*MAX(0,YEAR(DATE(2024+INT((ROW()-6)/12),MOD(ROW()-6,12)+2,0))-YEAR('سجل الأصول'!$I$6:$I$100)))/100,0)))))) -> 23000 | E6: =SUMPRODUCT(('سجل الأصول'!$D$6:$D$100="أثاث وديكور")*('سجل الأصول'!$N$6:$N$100<>"مهلك")*('سجل الأصول'!$E$6:$E$100-IF('سجل الأصول'!$I$6:$I$100>DATE(2024+INT((ROW()-6)/12),MOD(ROW()-6,12)+2,0),0,IF('سجل الأصول'!$K$6:$K$100="القسط الثابت",'سجل الأصول'!$G$6:$G$100*MIN(MAX(0,(YEAR(DATE(2024+INT((ROW()-6)/12),MOD(ROW()-6,12)+2,0))-YEAR('سجل الأصول'!$I$6:$I$100))*12+MONTH(DATE(2024+INT((ROW()-6)/12),MOD(ROW()-6,12)+2,0))-MONTH('سجل الأصول'!$I$6:$I$100)),'سجل الأصول'!$J$6:$J$100*12)/('سجل الأصول'!$J$6:$J$100*12),IF('سجل الأصول'!$K$6:$K$100="القسط المتناقص",'سجل الأصول'!$E$6:$E$100*(1-(1-'سجل الأصول'!$L$6:$L$100/100)^MIN(MAX(0,YEAR(DATE(2024+INT((ROW()-6)/12),MOD(ROW()-6,12)+2,0))-YEAR('سجل الأصول'!$I$6:$I$100)),'سجل الأصول'!$J$6:$J$100)),IF('سجل الأصول'!$K$6:$K$100="وحدات الإنتاج",'سجل الأصول'!$G$6:$G$100*MIN(100,'سجل الأصول'!$L$6:$L$100*MAX(0,YEAR(DATE(2024+INT((ROW()-6)/12),MOD(ROW()-6,12)+2,0))-YEAR('سجل الأصول'!$I$6:$I$100)))/100,0)))))) -> 95000 | F6: =SUMPRODUCT(('سجل الأصول'!$D$6:$D$100="تجهيزات")*('سجل الأصول'!$N$6:$N$100<>"مهلك")*('سجل الأصول'!$E$6:$E$100-IF('سجل الأصول'!$I$6:$I$100>DATE(2024+INT((ROW()-6)/12),MOD(ROW()-6,12)+2,0),0,IF('سجل الأصول'!$K$6:$K$100="القسط الثابت",'سجل الأصول'!$G$6:$G$100*MIN(MAX(0,(YEAR(DATE(2024+INT((ROW()-6)/12),MOD(ROW()-6,12)+2,0))-YEAR('سجل الأصول'!$I$6:$I$100))*12+MONTH(DATE(2024+INT((ROW()-6)/12),MOD(ROW()-6,12)+2,0))-MONTH('سجل الأصول'!$I$6:$I$100)),'سجل الأصول'!$J$6:$J$100*12)/('سجل الأصول'!$J$6:$J$100*12),IF('سجل الأصول'!$K$6:$K$100="القسط المتناقص",'سجل الأصول'!$E$6:$E$100*(1-(1-'سجل الأصول'!$L$6:$L$100/100)^MIN(MAX(0,YEAR(DATE(2024+INT((ROW()-6)/12),MOD(ROW()-6,12)+2,0))-YEAR('سجل الأصول'!$I$6:$I$100)),'سجل الأصول'!$J$6:$J$100)),IF('سجل الأصول'!$K$6:$K$100="وحدات الإنتاج",'سجل الأصول'!$G$6:$G$100*MIN(100,'سجل الأصول'!$L$6:$L$100*MAX(0,YEAR(DATE(2024+INT((ROW()-6)/12),MOD(ROW()-6,12)+2,0))-YEAR('سجل الأصول'!$I$6:$I$100)))/100,0)))))) -> 65000 | G6: =SUMPRODUCT(('سجل الأصول'!$D$6:$D$100="مركبات")*('سجل الأصول'!$N$6:$N$100<>"مهلك")*('سجل الأصول'!$E$6:$E$100-IF('سجل الأصول'!$I$6:$I$100>DATE(2024+INT((ROW()-6)/12),MOD(ROW()-6,12)+2,0),0,IF('سجل الأصول'!$K$6:$K$100="القسط الثابت",'سجل الأصول'!$G$6:$G$100*MIN(MAX(0,(YEAR(DATE(2024+INT((ROW()-6)/12),MOD(ROW()-6,12)+2,0))-YEAR('سجل الأصول'!$I$6:$I$100))*12+MONTH(DATE(2024+INT((ROW()-6)/12),MOD(ROW()-6,12)+2,0))-MONTH('سجل الأصول'!$I$6:$I$100)),'سجل الأصول'!$J$6:$J$100*12)/('سجل الأصول'!$J$6:$J$100*12),IF('سجل الأصول'!$K$6:$K$100="القسط المتناقص",'سجل الأصول'!$E$6:$E$100*(1-(1-'سجل الأصول'!$L$6:$L$100/100)^MIN(MAX(0,YEAR(DATE(2024+INT((ROW()-6)/12),MOD(ROW()-6,12)+2,0))-YEAR('سجل الأصول'!$I$6:$I$100)),'سجل الأصول'!$J$6:$J$100)),IF('سجل الأصول'!$K$6:$K$100="وحدات الإنتاج",'سجل الأصول'!$G$6:$G$100*MIN(100,'سجل الأصول'!$L$6:$L$100*MAX(0,YEAR(DATE(2024+INT((ROW()-6)/12),MOD(ROW()-6,12)+2,0))-YEAR('سجل الأصول'!$I$6:$I$100)))/100,0)))))) -> 85000 | H6: =SUM(C6:G6) -> 431000
B7: فبراير 2024 | C7: =SUMPRODUCT(('سجل الأصول'!$D$6:$D$100="معدات المطبخ")*('سجل الأصول'!$N$6:$N$100<>"مهلك")*('سجل الأصول'!$E$6:$E$100-IF('سجل الأصول'!$I$6:$I$100>DATE(2024+INT((ROW()-6)/12),MOD(ROW()-6,12)+2,0),0,IF('سجل الأصول'!$K$6:$K$100="القسط الثابت",'سجل الأصول'!$G$6:$G$100*MIN(MAX(0,(YEAR(DATE(2024+INT((ROW()-6)/12),MOD(ROW()-6,12)+2,0))-YEAR('سجل الأصول'!$I$6:$I$100))*12+MONTH(DATE(2024+INT((ROW()-6)/12),MOD(ROW()-6,12)+2,0))-MONTH('سجل الأصول'!$I$6:$I$100)),'سجل الأصول'!$J$6:$J$100*12)/('سجل الأصول'!$J$6:$J$100*12),IF('سجل الأصول'!$K$6:$K$100="القسط المتناقص",'سجل الأصول'!$E$6:$E$100*(1-(1-'سجل الأصول'!$L$6:$L$100/100)^MIN(MAX(0,YEAR(DATE(2024+INT((ROW()-6)/12),MOD(ROW()-6,12)+2,0))-YEAR('سجل الأصول'!$I$6:$I$100)),'سجل الأصول'!$J$6:$J$100)),IF('سجل الأصول'!$K$6:$K$100="وحدات الإنتاج",'سجل الأصول'!$G$6:$G$100*MIN(100,'سجل الأصول'!$L$6:$L$100*MAX(0,YEAR(DATE(2024+INT((ROW()-6)/12),MOD(ROW()-6,12)+2,0))-YEAR('سجل الأصول'!$I$6:$I$100)))/100,0)))))) -> 163000 | D7: =SUMPRODUCT(('سجل الأصول'!$D$6:$D$100="أنظمة تقنية")*('سجل الأصول'!$N$6:$N$100<>"مهلك")*('سجل الأصول'!$E$6:$E$100-IF('سجل الأصول'!$I$6:$I$100>DATE(2024+INT((ROW()-6)/12),MOD(ROW()-6,12)+2,0),0,IF('سجل الأصول'!$K$6:$K$100="القسط الثابت",'سجل الأصول'!$G$6:$G$100*MIN(MAX(0,(YEAR(DATE(2024+INT((ROW()-6)/12),MOD(ROW()-6,12)+2,0))-YEAR('سجل الأصول'!$I$6:$I$100))*12+MONTH(DATE(2024+INT((ROW()-6)/12),MOD(ROW()-6,12)+2,0))-MONTH('سجل الأصول'!$I$6:$I$100)),'سجل الأصول'!$J$6:$J$100*12)/('سجل الأصول'!$J$6:$J$100*12),IF('سجل الأصول'!$K$6:$K$100="القسط المتناقص",'سجل الأصول'!$E$6:$E$100*(1-(1-'سجل الأصول'!$L$6:$L$100/100)^MIN(MAX(0,YEAR(DATE(2024+INT((ROW()-6)/12),MOD(ROW()-6,12)+2,0))-YEAR('سجل الأصول'!$I$6:$I$100)),'سجل الأصول'!$J$6:$J$100)),IF('سجل الأصول'!$K$6:$K$100="وحدات الإنتاج",'سجل الأصول'!$G$6:$G$100*MIN(100,'سجل الأصول'!$L$6:$L$100*MAX(0,YEAR(DATE(2024+INT((ROW()-6)/12),MOD(ROW()-6,12)+2,0))-YEAR('سجل الأصول'!$I$6:$I$100)))/100,0)))))) -> 23000 | E7: =SUMPRODUCT(('سجل الأصول'!$D$6:$D$100="أثاث وديكور")*('سجل الأصول'!$N$6:$N$100<>"مهلك")*('سجل الأصول'!$E$6:$E$100-IF('سجل الأصول'!$I$6:$I$100>DATE(2024+INT((ROW()-6)/12),MOD(ROW()-6,12)+2,0),0,IF('سجل الأصول'!$K$6:$K$100="القسط الثابت",'سجل الأصول'!$G$6:$G$100*MIN(MAX(0,(YEAR(DATE(2024+INT((ROW()-6)/12),MOD(ROW()-6,12)+2,0))-YEAR('سجل الأصول'!$I$6:$I$100))*12+MONTH(DATE(2024+INT((ROW()-6)/12),MOD(ROW()-6,12)+2,0))-MONTH('سجل الأصول'!$I$6:$I$100)),'سجل الأصول'!$J$6:$J$100*12)/('سجل الأصول'!$J$6:$J$100*12),IF('سجل الأصول'!$K$6:$K$100="القسط المتناقص",'سجل الأصول'!$E$6:$E$100*(1-(1-'سجل الأصول'!$L$6:$L$100/100)^MIN(MAX(0,YEAR(DATE(2024+INT((ROW()-6)/12),MOD(ROW()-6,12)+2,0))-YEAR('سجل الأصول'!$I$6:$I$100)),'سجل الأصول'!$J$6:$J$100)),IF('سجل الأصول'!$K$6:$K$100="وحدات الإنتاج",'سجل الأصول'!$G$6:$G$100*MIN(100,'سجل الأصول'!$L$6:$L$100*MAX(0,YEAR(DATE(2024+INT((ROW()-6)/12),MOD(ROW()-6,12)+2,0))-YEAR('سجل الأصول'!$I$6:$I$100)))/100,0)))))) -> 95000 | F7: =SUMPRODUCT(('سجل الأصول'!$D$6:$D$100="تجهيزات")*('سجل الأصول'!$N$6:$N$100<>"مهلك")*('سجل الأصول'!$E$6:$E$100-IF('سجل الأصول'!$I$6:$I$100>DATE(2024+INT((ROW()-6)/12),MOD(ROW()-6,12)+2,0),0,IF('سجل الأصول'!$K$6:$K$100="القسط الثابت",'سجل الأصول'!$G$6:$G$100*MIN(MAX(0,(YEAR(DATE(2024+INT((ROW()-6)/12),MOD(ROW()-6,12)+2,0))-YEAR('سجل الأصول'!$I$6:$I$100))*12+MONTH(DATE(2024+INT((ROW()-6)/12),MOD(ROW()-6,12)+2,0))-MONTH('سجل الأصول'!$I$6:$I$100)),'سجل الأصول'!$J$6:$J$100*12)/('سجل الأصول'!$J$6:$J$100*12),IF('سجل الأصول'!$K$6:$K$100="القسط المتناقص",'سجل الأصول'!$E$6:$E$100*(1-(1-'سجل الأصول'!$L$6:$L$100/100)^MIN(MAX(0,YEAR(DATE(2024+INT((ROW()-6)/12),MOD(ROW()-6,12)+2,0))-YEAR('سجل الأصول'!$I$6:$I$100)),'سجل الأصول'!$J$6:$J$100)),IF('سجل الأصول'!$K$6:$K$100="وحدات الإنتاج",'سجل الأصول'!$G$6:$G$100*MIN(100,'سجل الأصول'!$L$6:$L$100*MAX(0,YEAR(DATE(2024+INT((ROW()-6)/12),MOD(ROW()-6,12)+2,0))-YEAR('سجل الأصول'!$I$6:$I$100)))/100,0)))))) -> 65000 | G7: =SUMPRODUCT(('سجل الأصول'!$D$6:$D$100="مركبات")*('سجل الأصول'!$N$6:$N$100<>"مهلك")*('سجل الأصول'!$E$6:$E$100-IF('سجل الأصول'!$I$6:$I$100>DATE(2024+INT((ROW()-6)/12),MOD(ROW()-6,12)+2,0),0,IF('سجل الأصول'!$K$6:$K$100="القسط الثابت",'سجل الأصول'!$G$6:$G$100*MIN(MAX(0,(YEAR(DATE(2024+INT((ROW()-6)/12),MOD(ROW()-6,12)+2,0))-YEAR('سجل الأصول'!$I$6:$I$100))*12+MONTH(DATE(2024+INT((ROW()-6)/12),MOD(ROW()-6,12)+2,0))-MONTH('سجل الأصول'!$I$6:$I$100)),'سجل الأصول'!$J$6:$J$100*12)/('سجل الأصول'!$J$6:$J$100*12),IF('سجل الأصول'!$K$6:$K$100="القسط المتناقص",'سجل الأصول'!$E$6:$E$100*(1-(1-'سجل الأصول'!$L$6:$L$100/100)^MIN(MAX(0,YEAR(DATE(2024+INT((ROW()-6)/12),MOD(ROW()-6,12)+2,0))-YEAR('سجل الأصول'!$I$6:$I$100)),'سجل الأصول'!$J$6:$J$100)),IF('سجل الأصول'!$K$6:$K$100="وحدات الإنتاج",'سجل الأصول'!$G$6:$G$100*MIN(100,'سجل الأصول'!$L$6:$L$100*MAX(0,YEAR(DATE(2024+INT((ROW()-6)/12),MOD(ROW()-6,12)+2,0))-YEAR('سجل الأصول'!$I$6:$I$100)))/100,0)))))) -> 85000 | H7: =SUM(C7:G7) -> 431000
B8: مارس 2024 | C8: =SUMPRODUCT(('سجل الأصول'!$D$6:$D$100="معدات المطبخ")*('سجل الأصول'!$N$6:$N$100<>"مهلك")*('سجل الأصول'!$E$6:$E$100-IF('سجل الأصول'!$I$6:$I$100>DATE(2024+INT((ROW()-6)/12),MOD(ROW()-6,12)+2,0),0,IF('سجل الأصول'!$K$6:$K$100="القسط الثابت",'سجل الأصول'!$G$6:$G$100*MIN(MAX(0,(YEAR(DATE(2024+INT((ROW()-6)/12),MOD(ROW()-6,12)+2,0))-YEAR('سجل الأصول'!$I$6:$I$100))*12+MONTH(DATE(2024+INT((ROW()-6)/12),MOD(ROW()-6,12)+2,0))-MONTH('سجل الأصول'!$I$6:$I$100)),'سجل الأصول'!$J$6:$J$100*12)/('سجل الأصول'!$J$6:$J$100*12),IF('سجل الأصول'!$K$6:$K$100="القسط المتناقص",'سجل الأصول'!$E$6:$E$100*(1-(1-'سجل الأصول'!$L$6:$L$100/100)^MIN(MAX(0,YEAR(DATE(2024+INT((ROW()-6)/12),MOD(ROW()-6,12)+2,0))-YEAR('سجل الأصول'!$I$6:$I$100)),'سجل الأصول'!$J$6:$J$100)),IF('سجل الأصول'!$K$6:$K$100="وحدات الإنتاج",'سجل الأصول'!$G$6:$G$100*MIN(100,'سجل الأصول'!$L$6:$L$100*MAX(0,YEAR(DATE(2024+INT((ROW()-6)/12),MOD(ROW()-6,12)+2,0))-YEAR('سجل الأصول'!$I$6:$I$100)))/100,0)))))) -> 163000 | D8: =SUMPRODUCT(('سجل الأصول'!$D$6:$D$100="أنظمة تقنية")*('سجل الأصول'!$N$6:$N$100<>"مهلك")*('سجل الأصول'!$E$6:$E$100-IF('سجل الأصول'!$I$6:$I$100>DATE(2024+INT((ROW()-6)/12),MOD(ROW()-6,12)+2,0),0,IF('سجل الأصول'!$K$6:$K$100="القسط الثابت",'سجل الأصول'!$G$6:$G$100*MIN(MAX(0,(YEAR(DATE(2024+INT((ROW()-6)/12),MOD(ROW()-6,12)+2,0))-YEAR('سجل الأصول'!$I$6:$I$100))*12+MONTH(DATE(2024+INT((ROW()-6)/12),MOD(ROW()-6,12)+2,0))-MONTH('سجل الأصول'!$I$6:$I$100)),'سجل الأصول'!$J$6:$J$100*12)/('سجل الأصول'!$J$6:$J$100*12),IF('سجل الأصول'!$K$6:$K$100="القسط المتناقص",'سجل الأصول'!$E$6:$E$100*(1-(1-'سجل الأصول'!$L$6:$L$100/100)^MIN(MAX(0,YEAR(DATE(2024+INT((ROW()-6)/12),MOD(ROW()-6,12)+2,0))-YEAR('سجل الأصول'!$I$6:$I$100)),'سجل الأصول'!$J$6:$J$100)),IF('سجل الأصول'!$K$6:$K$100="وحدات الإنتاج",'سجل الأصول'!$G$6:$G$100*MIN(100,'سجل الأصول'!$L$6:$L$100*MAX(0,YEAR(DATE(2024+INT((ROW()-6)/12),MOD(ROW()-6,12)+2,0))-YEAR('سجل الأصول'!$I$6:$I$100)))/100,0)))))) -> 23000 | E8: =SUMPRODUCT(('سجل الأصول'!$D$6:$D$100="أثاث وديكور")*('سجل الأصول'!$N$6:$N$100<>"مهلك")*('سجل الأصول'!$E$6:$E$100-IF('سجل الأصول'!$I$6:$I$100>DATE(2024+INT((ROW()-6)/12),MOD(ROW()-6,12)+2,0),0,IF('سجل الأصول'!$K$6:$K$100="القسط الثابت",'سجل الأصول'!$G$6:$G$100*MIN(MAX(0,(YEAR(DATE(2024+INT((ROW()-6)/12),MOD(ROW()-6,12)+2,0))-YEAR('سجل الأصول'!$I$6:$I$100))*12+MONTH(DATE(2024+INT((ROW()-6)/12),MOD(ROW()-6,12)+2,0))-MONTH('سجل الأصول'!$I$6:$I$100)),'سجل الأصول'!$J$6:$J$100*12)/('سجل الأصول'!$J$6:$J$100*12),IF('سجل الأصول'!$K$6:$K$100="القسط المتناقص",'سجل الأصول'!$E$6:$E$100*(1-(1-'سجل الأصول'!$L$6:$L$100/100)^MIN(MAX(0,YEAR(DATE(2024+INT((ROW()-6)/12),MOD(ROW()-6,12)+2,0))-YEAR('سجل الأصول'!$I$6:$I$100)),'سجل الأصول'!$J$6:$J$100)),IF('سجل الأصول'!$K$6:$K$100="وحدات الإنتاج",'سجل الأصول'!$G$6:$G$100*MIN(100,'سجل الأصول'!$L$6:$L$100*MAX(0,YEAR(DATE(2024+INT((ROW()-6)/12),MOD(ROW()-6,12)+2,0))-YEAR('سجل الأصول'!$I$6:$I$100)))/100,0)))))) -> 95000 | F8: =SUMPRODUCT(('سجل الأصول'!$D$6:$D$100="تجهيزات")*('سجل الأصول'!$N$6:$N$100<>"مهلك")*('سجل الأصول'!$E$6:$E$100-IF('سجل الأصول'!$I$6:$I$100>DATE(2024+INT((ROW()-6)/12),MOD(ROW()-6,12)+2,0),0,IF('سجل الأصول'!$K$6:$K$100="القسط الثابت",'سجل الأصول'!$G$6:$G$100*MIN(MAX(0,(YEAR(DATE(2024+INT((ROW()-6)/12),MOD(ROW()-6,12)+2,0))-YEAR('سجل الأصول'!$I$6:$I$100))*12+MONTH(DATE(2024+INT((ROW()-6)/12),MOD(ROW()-6,12)+2,0))-MONTH('سجل الأصول'!$I$6:$I$100)),'سجل الأصول'!$J$6:$J$100*12)/('سجل الأصول'!$J$6:$J$100*12),IF('سجل الأصول'!$K$6:$K$100="القسط المتناقص",'سجل الأصول'!$E$6:$E$100*(1-(1-'سجل الأصول'!$L$6:$L$100/100)^MIN(MAX(0,YEAR(DATE(2024+INT((ROW()-6)/12),MOD(ROW()-6,12)+2,0))-YEAR('سجل الأصول'!$I$6:$I$100)),'سجل الأصول'!$J$6:$J$100)),IF('سجل الأصول'!$K$6:$K$100="وحدات الإنتاج",'سجل الأصول'!$G$6:$G$100*MIN(100,'سجل الأصول'!$L$6:$L$100*MAX(0,YEAR(DATE(2024+INT((ROW()-6)/12),MOD(ROW()-6,12)+2,0))-YEAR('سجل الأصول'!$I$6:$I$100)))/100,0)))))) -> 65000 | G8: =SUMPRODUCT(('سجل الأصول'!$D$6:$D$100="مركبات")*('سجل الأصول'!$N$6:$N$100<>"مهلك")*('سجل الأصول'!$E$6:$E$100-IF('سجل الأصول'!$I$6:$I$100>DATE(2024+INT((ROW()-6)/12),MOD(ROW()-6,12)+2,0),0,IF('سجل الأصول'!$K$6:$K$100="القسط الثابت",'سجل الأصول'!$G$6:$G$100*MIN(MAX(0,(YEAR(DATE(2024+INT((ROW()-6)/12),MOD(ROW()-6,12)+2,0))-YEAR('سجل الأصول'!$I$6:$I$100))*12+MONTH(DATE(2024+INT((ROW()-6)/12),MOD(ROW()-6,12)+2,0))-MONTH('سجل الأصول'!$I$6:$I$100)),'سجل الأصول'!$J$6:$J$100*12)/('سجل الأصول'!$J$6:$J$100*12),IF('سجل الأصول'!$K$6:$K$100="القسط المتناقص",'سجل الأصول'!$E$6:$E$100*(1-(1-'سجل الأصول'!$L$6:$L$100/100)^MIN(MAX(0,YEAR(DATE(2024+INT((ROW()-6)/12),MOD(ROW()-6,12)+2,0))-YEAR('سجل الأصول'!$I$6:$I$100)),'سجل الأصول'!$J$6:$J$100)),IF('سجل الأصول'!$K$6:$K$100="وحدات الإنتاج",'سجل الأصول'!$G$6:$G$100*MIN(100,'سجل الأصول'!$L$6:$L$100*MAX(0,YEAR(DATE(2024+INT((ROW()-6)/12),MOD(ROW()-6,12)+2,0))-YEAR('سجل الأصول'!$I$6:$I$100)))/100,0)))))) -> 85000 | H8: =SUM(C8:G8) -> 431000
B9: أبريل 2024 | C9: =SUMPRODUCT(('سجل الأصول'!$D$6:$D$100="معدات المطبخ")*('سجل الأصول'!$N$6:$N$100<>"مهلك")*('سجل الأصول'!$E$6:$E$100-IF('سجل الأصول'!$I$6:$I$100>DATE(2024+INT((ROW()-6)/12),MOD(ROW()-6,12)+2,0),0,IF('سجل الأصول'!$K$6:$K$100="القسط الثابت",'سجل الأصول'!$G$6:$G$100*MIN(MAX(0,(YEAR(DATE(2024+INT((ROW()-6)/12),MOD(ROW()-6,12)+2,0))-YEAR('سجل الأصول'!$I$6:$I$100))*12+MONTH(DATE(2024+INT((ROW()-6)/12),MOD(ROW()-6,12)+2,0))-MONTH('سجل الأصول'!$I$6:$I$100)),'سجل الأصول'!$J$6:$J$100*12)/('سجل الأصول'!$J$6:$J$100*12),IF('سجل الأصول'!$K$6:$K$100="القسط المتناقص",'سجل الأصول'!$E$6:$E$100*(1-(1-'سجل الأصول'!$L$6:$L$100/100)^MIN(MAX(0,YEAR(DATE(2024+INT((ROW()-6)/12),MOD(ROW()-6,12)+2,0))-YEAR('سجل الأصول'!$I$6:$I$100)),'سجل الأصول'!$J$6:$J$100)),IF('سجل الأصول'!$K$6:$K$100="وحدات الإنتاج",'سجل الأصول'!$G$6:$G$100*MIN(100,'سجل الأصول'!$L$6:$L$100*MAX(0,YEAR(DATE(2024+INT((ROW()-6)/12),MOD(ROW()-6,12)+2,0))-YEAR('سجل الأصول'!$I$6:$I$100)))/100,0)))))) -> 161833.33 | D9: =SUMPRODUCT(('سجل الأصول'!$D$6:$D$100="أنظمة تقنية")*('سجل الأصول'!$N$6:$N$100<>"مهلك")*('سجل الأصول'!$E$6:$E$100-IF('سجل الأصول'!$I$6:$I$100>DATE(2024+INT((ROW()-6)/12),MOD(ROW()-6,12)+2,0),0,IF('سجل الأصول'!$K$6:$K$100="القسط الثابت",'سجل الأصول'!$G$6:$G$100*MIN(MAX(0,(YEAR(DATE(2024+INT((ROW()-6)/12),MOD(ROW()-6,12)+2,0))-YEAR('سجل الأصول'!$I$6:$I$100))*12+MONTH(DATE(2024+INT((ROW()-6)/12),MOD(ROW()-6,12)+2,0))-MONTH('سجل الأصول'!$I$6:$I$100)),'سجل الأصول'!$J$6:$J$100*12)/('سجل الأصول'!$J$6:$J$100*12),IF('سجل الأصول'!$K$6:$K$100="القسط المتناقص",'سجل الأصول'!$E$6:$E$100*(1-(1-'سجل الأصول'!$L$6:$L$100/100)^MIN(MAX(0,YEAR(DATE(2024+INT((ROW()-6)/12),MOD(ROW()-6,12)+2,0))-YEAR('سجل الأصول'!$I$6:$I$100)),'سجل الأصول'!$J$6:$J$100)),IF('سجل الأصول'!$K$6:$K$100="وحدات الإنتاج",'سجل الأصول'!$G$6:$G$100*MIN(100,'سجل الأصول'!$L$6:$L$100*MAX(0,YEAR(DATE(2024+INT((ROW()-6)/12),MOD(ROW()-6,12)+2,0))-YEAR('سجل الأصول'!$I$6:$I$100)))/100,0)))))) -> 22533.333 | E9: =SUMPRODUCT(('سجل الأصول'!$D$6:$D$100="أثاث وديكور")*('سجل الأصول'!$N$6:$N$100<>"مهلك")*('سجل الأصول'!$E$6:$E$100-IF('سجل الأصول'!$I$6:$I$100>DATE(2024+INT((ROW()-6)/12),MOD(ROW()-6,12)+2,0),0,IF('سجل الأصول'!$K$6:$K$100="القسط الثابت",'سجل الأصول'!$G$6:$G$100*MIN(MAX(0,(YEAR(DATE(2024+INT((ROW()-6)/12),MOD(ROW()-6,12)+2,0))-YEAR('سجل الأصول'!$I$6:$I$100))*12+MONTH(DATE(2024+INT((ROW()-6)/12),MOD(ROW()-6,12)+2,0))-MONTH('سجل الأصول'!$I$6:$I$100)),'سجل الأصول'!$J$6:$J$100*12)/('سجل الأصول'!$J$6:$J$100*12),IF('سجل الأصول'!$K$6:$K$100="القسط المتناقص",'سجل الأصول'!$E$6:$E$100*(1-(1-'سجل الأصول'!$L$6:$L$100/100)^MIN(MAX(0,YEAR(DATE(2024+INT((ROW()-6)/12),MOD(ROW()-6,12)+2,0))-YEAR('سجل الأصول'!$I$6:$I$100)),'سجل الأصول'!$J$6:$J$100)),IF('سجل الأصول'!$K$6:$K$100="وحدات الإنتاج",'سجل الأصول'!$G$6:$G$100*MIN(100,'سجل الأصول'!$L$6:$L$100*MAX(0,YEAR(DATE(2024+INT((ROW()-6)/12),MOD(ROW()-6,12)+2,0))-YEAR('سجل الأصول'!$I$6:$I$100)))/100,0)))))) -> 94300 | F9: =SUMPRODUCT(('سجل الأصول'!$D$6:$D$100="تجهيزات")*('سجل الأصول'!$N$6:$N$100<>"مهلك")*('سجل الأصول'!$E$6:$E$100-IF('سجل الأصول'!$I$6:$I$100>DATE(2024+INT((ROW()-6)/12),MOD(ROW()-6,12)+2,0),0,IF('سجل الأصول'!$K$6:$K$100="القسط الثابت",'سجل الأصول'!$G$6:$G$100*MIN(MAX(0,(YEAR(DATE(2024+INT((ROW()-6)/12),MOD(ROW()-6,12)+2,0))-YEAR('سجل الأصول'!$I$6:$I$100))*12+MONTH(DATE(2024+INT((ROW()-6)/12),MOD(ROW()-6,12)+2,0))-MONTH('سجل الأصول'!$I$6:$I$100)),'سجل الأصول'!$J$6:$J$100*12)/('سجل الأصول'!$J$6:$J$100*12),IF('سجل الأصول'!$K$6:$K$100="القسط المتناقص",'سجل الأصول'!$E$6:$E$100*(1-(1-'سجل الأصول'!$L$6:$L$100/100)^MIN(MAX(0,YEAR(DATE(2024+INT((ROW()-6)/12),MOD(ROW()-6,12)+2,0))-YEAR('سجل الأصول'!$I$6:$I$100)),'سجل الأصول'!$J$6:$J$100)),IF('سجل الأصول'!$K$6:$K$100="وحدات الإنتاج",'سجل الأصول'!$G$6:$G$100*MIN(100,'سجل الأصول'!$L$6:$L$100*MAX(0,YEAR(DATE(2024+INT((ROW()-6)/12),MOD(ROW()-6,12)+2,0))-YEAR('سجل الأصول'!$I$6:$I$100)))/100,0)))))) -> 64766.667 | G9: =SUMPRODUCT(('سجل الأصول'!$D$6:$D$100="مركبات")*('سجل الأصول'!$N$6:$N$100<>"مهلك")*('سجل الأصول'!$E$6:$E$100-IF('سجل الأصول'!$I$6:$I$100>DATE(2024+INT((ROW()-6)/12),MOD(ROW()-6,12)+2,0),0,IF('سجل الأصول'!$K$6:$K$100="القسط الثابت",'سجل الأصول'!$G$6:$G$100*MIN(MAX(0,(YEAR(DATE(2024+INT((ROW()-6)/12),MOD(ROW()-6,12)+2,0))-YEAR('سجل الأصول'!$I$6:$I$100))*12+MONTH(DATE(2024+INT((ROW()-6)/12),MOD(ROW()-6,12)+2,0))-MONTH('سجل الأصول'!$I$6:$I$100)),'سجل الأصول'!$J$6:$J$100*12)/('سجل الأصول'!$J$6:$J$100*12),IF('سجل الأصول'!$K$6:$K$100="القسط المتناقص",'سجل الأصول'!$E$6:$E$100*(1-(1-'سجل الأصول'!$L$6:$L$100/100)^MIN(MAX(0,YEAR(DATE(2024+INT((ROW()-6)/12),MOD(ROW()-6,12)+2,0))-YEAR('سجل الأصول'!$I$6:$I$100)),'سجل الأصول'!$J$6:$J$100)),IF('سجل الأصول'!$K$6:$K$100="وحدات الإنتاج",'سجل الأصول'!$G$6:$G$100*MIN(100,'سجل الأصول'!$L$6:$L$100*MAX(0,YEAR(DATE(2024+INT((ROW()-6)/12),MOD(ROW()-6,12)+2,0))-YEAR('سجل الأصول'!$I$6:$I$100)))/100,0)))))) -> 84766.667 | H9: =SUM(C9:G9) -> 428200
B10: مايو 2024 | C10: =SUMPRODUCT(('سجل الأصول'!$D$6:$D$100="معدات المطبخ")*('سجل الأصول'!$N$6:$N$100<>"مهلك")*('سجل الأصول'!$E$6:$E$100-IF('سجل الأصول'!$I$6:$I$100>DATE(2024+INT((ROW()-6)/12),MOD(ROW()-6,12)+2,0),0,IF('سجل الأصول'!$K$6:$K$100="القسط الثابت",'سجل الأصول'!$G$6:$G$100*MIN(MAX(0,(YEAR(DATE(2024+INT((ROW()-6)/12),MOD(ROW()-6,12)+2,0))-YEAR('سجل الأصول'!$I$6:$I$100))*12+MONTH(DATE(2024+INT((ROW()-6)/12),MOD(ROW()-6,12)+2,0))-MONTH('سجل الأصول'!$I$6:$I$100)),'سجل الأصول'!$J$6:$J$100*12)/('سجل الأصول'!$J$6:$J$100*12),IF('سجل الأصول'!$K$6:$K$100="القسط المتناقص",'سجل الأصول'!$E$6:$E$100*(1-(1-'سجل الأصول'!$L$6:$L$100/100)^MIN(MAX(0,YEAR(DATE(2024+INT((ROW()-6)/12),MOD(ROW()-6,12)+2,0))-YEAR('سجل الأصول'!$I$6:$I$100)),'سجل الأصول'!$J$6:$J$100)),IF('سجل الأصول'!$K$6:$K$100="وحدات الإنتاج",'سجل الأصول'!$G$6:$G$100*MIN(100,'سجل الأصول'!$L$6:$L$100*MAX(0,YEAR(DATE(2024+INT((ROW()-6)/12),MOD(ROW()-6,12)+2,0))-YEAR('سجل الأصول'!$I$6:$I$100)))/100,0)))))) -> 163000 | D10: =SUMPRODUCT(('سجل الأصول'!$D$6:$D$100="أنظمة تقنية")*('سجل الأصول'!$N$6:$N$100<>"مهلك")*('سجل الأصول'!$E$6:$E$100-IF('سجل الأصول'!$I$6:$I$100>DATE(2024+INT((ROW()-6)/12),MOD(ROW()-6,12)+2,0),0,IF('سجل الأصول'!$K$6:$K$100="القسط الثابت",'سجل الأصول'!$G$6:$G$100*MIN(MAX(0,(YEAR(DATE(2024+INT((ROW()-6)/12),MOD(ROW()-6,12)+2,0))-YEAR('سجل الأصول'!$I$6:$I$100))*12+MONTH(DATE(2024+INT((ROW()-6)/12),MOD(ROW()-6,12)+2,0))-MONTH('سجل الأصول'!$I$6:$I$100)),'سجل الأصول'!$J$6:$J$100*12)/('سجل الأصول'!$J$6:$J$100*12),IF('سجل الأصول'!$K$6:$K$100="القسط المتناقص",'سجل الأصول'!$E$6:$E$100*(1-(1-'سجل الأصول'!$L$6:$L$100/100)^MIN(MAX(0,YEAR(DATE(2024+INT((ROW()-6)/12),MOD(ROW()-6,12)+2,0))-YEAR('سجل الأصول'!$I$6:$I$100)),'سجل الأصول'!$J$6:$J$100)),IF('سجل الأصول'!$K$6:$K$100="وحدات الإنتاج",'سجل الأصول'!$G$6:$G$100*MIN(100,'سجل الأصول'!$L$6:$L$100*MAX(0,YEAR(DATE(2024+INT((ROW()-6)/12),MOD(ROW()-6,12)+2,0))-YEAR('سجل الأصول'!$I$6:$I$100)))/100,0)))))) -> 23000 | E10: =SUMPRODUCT(('سجل الأصول'!$D$6:$D$100="أثاث وديكور")*('سجل الأصول'!$N$6:$N$100<>"مهلك")*('سجل الأصول'!$E$6:$E$100-IF('سجل الأصول'!$I$6:$I$100>DATE(2024+INT((ROW()-6)/12),MOD(ROW()-6,12)+2,0),0,IF('سجل الأصول'!$K$6:$K$100="القسط الثابت",'سجل الأصول'!$G$6:$G$100*MIN(MAX(0,(YEAR(DATE(2024+INT((ROW()-6)/12),MOD(ROW()-6,12)+2,0))-YEAR('سجل الأصول'!$I$6:$I$100))*12+MONTH(DATE(2024+INT((ROW()-6)/12),MOD(ROW()-6,12)+2,0))-MONTH('سجل الأصول'!$I$6:$I$100)),'سجل الأصول'!$J$6:$J$100*12)/('سجل الأصول'!$J$6:$J$100*12),IF('سجل الأصول'!$K$6:$K$100="القسط المتناقص",'سجل الأصول'!$E$6:$E$100*(1-(1-'سجل الأصول'!$L$6:$L$100/100)^MIN(MAX(0,YEAR(DATE(2024+INT((ROW()-6)/12),MOD(ROW()-6,12)+2,0))-YEAR('سجل الأصول'!$I$6:$I$100)),'سجل الأصول'!$J$6:$J$100)),IF('سجل الأصول'!$K$6:$K$100="وحدات الإنتاج",'سجل الأصول'!$G$6:$G$100*MIN(100,'سجل الأصول'!$L$6:$L$100*MAX(0,YEAR(DATE(2024+INT((ROW()-6)/12),MOD(ROW()-6,12)+2,0))-YEAR('سجل الأصول'!$I$6:$I$100)))/100,0)))))) -> 95000 | F10: =SUMPRODUCT(('سجل الأصول'!$D$6:$D$100="تجهيزات")*('سجل الأصول'!$N$6:$N$100<>"مهلك")*('سجل الأصول'!$E$6:$E$100-IF('سجل الأصول'!$I$6:$I$100>DATE(2024+INT((ROW()-6)/12),MOD(ROW()-6,12)+2,0),0,IF('سجل الأصول'!$K$6:$K$100="القسط الثابت",'سجل الأصول'!$G$6:$G$100*MIN(MAX(0,(YEAR(DATE(2024+INT((ROW()-6)/12),MOD(ROW()-6,12)+2,0))-YEAR('سجل الأصول'!$I$6:$I$100))*12+MONTH(DATE(2024+INT((ROW()-6)/12),MOD(ROW()-6,12)+2,0))-MONTH('سجل الأصول'!$I$6:$I$100)),'سجل الأصول'!$J$6:$J$100*12)/('سجل الأصول'!$J$6:$J$100*12),IF('سجل الأصول'!$K$6:$K$100="القسط المتناقص",'سجل الأصول'!$E$6:$E$100*(1-(1-'سجل الأصول'!$L$6:$L$100/100)^MIN(MAX(0,YEAR(DATE(2024+INT((ROW()-6)/12),MOD(ROW()-6,12)+2,0))-YEAR('سجل الأصول'!$I$6:$I$100)),'سجل الأصول'!$J$6:$J$100)),IF('سجل الأصول'!$K$6:$K$100="وحدات الإنتاج",'سجل الأصول'!$G$6:$G$100*MIN(100,'سجل الأصول'!$L$6:$L$100*MAX(0,YEAR(DATE(2024+INT((ROW()-6)/12),MOD(ROW()-6,12)+2,0))-YEAR('سجل الأصول'!$I$6:$I$100)))/100,0)))))) -> 65000 | G10: =SUMPRODUCT(('سجل الأصول'!$D$6:$D$100="مركبات")*('سجل الأصول'!$N$6:$N$100<>"مهلك")*('سجل الأصول'!$E$6:$E$100-IF('سجل الأصول'!$I$6:$I$100>DATE(2024+INT((ROW()-6)/12),MOD(ROW()-6,12)+2,0),0,IF('سجل الأصول'!$K$6:$K$100="القسط الثابت",'سجل الأصول'!$G$6:$G$100*MIN(MAX(0,(YEAR(DATE(2024+INT((ROW()-6)/12),MOD(ROW()-6,12)+2,0))-YEAR('سجل الأصول'!$I$6:$I$100))*12+MONTH(DATE(2024+INT((ROW()-6)/12),MOD(ROW()-6,12)+2,0))-MONTH('سجل الأصول'!$I$6:$I$100)),'سجل الأصول'!$J$6:$J$100*12)/('سجل الأصول'!$J$6:$J$100*12),IF('سجل الأصول'!$K$6:$K$100="القسط المتناقص",'سجل الأصول'!$E$6:$E$100*(1-(1-'سجل الأصول'!$L$6:$L$100/100)^MIN(MAX(0,YEAR(DATE(2024+INT((ROW()-6)/12),MOD(ROW()-6,12)+2,0))-YEAR('سجل الأصول'!$I$6:$I$100)),'سجل الأصول'!$J$6:$J$100)),IF('سجل الأصول'!$K$6:$K$100="وحدات الإنتاج",'سجل الأصول'!$G$6:$G$100*MIN(100,'سجل الأصول'!$L$6:$L$100*MAX(0,YEAR(DATE(2024+INT((ROW()-6)/12),MOD(ROW()-6,12)+2,0))-YEAR('سجل الأصول'!$I$6:$I$100)))/100,0)))))) -> 85000 | H10: =SUM(C10:G10) -> 431000
B11: يونيو 2024 | C11: =SUMPRODUCT(('سجل الأصول'!$D$6:$D$100="معدات المطبخ")*('سجل الأصول'!$N$6:$N$100<>"مهلك")*('سجل الأصول'!$E$6:$E$100-IF('سجل الأصول'!$I$6:$I$100>DATE(2024+INT((ROW()-6)/12),MOD(ROW()-6,12)+2,0),0,IF('سجل الأصول'!$K$6:$K$100="القسط الثابت",'سجل الأصول'!$G$6:$G$100*MIN(MAX(0,(YEAR(DATE(2024+INT((ROW()-6)/12),MOD(ROW()-6,12)+2,0))-YEAR('سجل الأصول'!$I$6:$I$100))*12+MONTH(DATE(2024+INT((ROW()-6)/12),MOD(ROW()-6,12)+2,0))-MONTH('سجل الأصول'!$I$6:$I$100)),'سجل الأصول'!$J$6:$J$100*12)/('سجل الأصول'!$J$6:$J$100*12),IF('سجل الأصول'!$K$6:$K$100="القسط المتناقص",'سجل الأصول'!$E$6:$E$100*(1-(1-'سجل الأصول'!$L$6:$L$100/100)^MIN(MAX(0,YEAR(DATE(2024+INT((ROW()-6)/12),MOD(ROW()-6,12)+2,0))-YEAR('سجل الأصول'!$I$6:$I$100)),'سجل الأصول'!$J$6:$J$100)),IF('سجل الأصول'!$K$6:$K$100="وحدات الإنتاج",'سجل الأصول'!$G$6:$G$100*MIN(100,'سجل الأصول'!$L$6:$L$100*MAX(0,YEAR(DATE(2024+INT((ROW()-6)/12),MOD(ROW()-6,12)+2,0))-YEAR('سجل الأصول'!$I$6:$I$100)))/100,0)))))) -> 163000 | D11: =SUMPRODUCT(('سجل الأصول'!$D$6:$D$100="أنظمة تقنية")*('سجل الأصول'!$N$6:$N$100<>"مهلك")*('سجل الأصول'!$E$6:$E$100-IF('سجل الأصول'!$I$6:$I$100>DATE(2024+INT((ROW()-6)/12),MOD(ROW()-6,12)+2,0),0,IF('سجل الأصول'!$K$6:$K$100="القسط الثابت",'سجل الأصول'!$G$6:$G$100*MIN(MAX(0,(YEAR(DATE(2024+INT((ROW()-6)/12),MOD(ROW()-6,12)+2,0))-YEAR('سجل الأصول'!$I$6:$I$100))*12+MONTH(DATE(2024+INT((ROW()-6)/12),MOD(ROW()-6,12)+2,0))-MONTH('سجل الأصول'!$I$6:$I$100)),'سجل الأصول'!$J$6:$J$100*12)/('سجل الأصول'!$J$6:$J$100*12),IF('سجل الأصول'!$K$6:$K$100="القسط المتناقص",'سجل الأصول'!$E$6:$E$100*(1-(1-'سجل الأصول'!$L$6:$L$100/100)^MIN(MAX(0,YEAR(DATE(2024+INT((ROW()-6)/12),MOD(ROW()-6,12)+2,0))-YEAR('سجل الأصول'!$I$6:$I$100)),'سجل الأصول'!$J$6:$J$100)),IF('سجل الأصول'!$K$6:$K$100="وحدات الإنتاج",'سجل الأصول'!$G$6:$G$100*MIN(100,'سجل الأصول'!$L$6:$L$100*MAX(0,YEAR(DATE(2024+INT((ROW()-6)/12),MOD(ROW()-6,12)+2,0))-YEAR('سجل الأصول'!$I$6:$I$100)))/100,0)))))) -> 23000 | E11: =SUMPRODUCT(('سجل الأصول'!$D$6:$D$100="أثاث وديكور")*('سجل الأصول'!$N$6:$N$100<>"مهلك")*('سجل الأصول'!$E$6:$E$100-IF('سجل الأصول'!$I$6:$I$100>DATE(2024+INT((ROW()-6)/12),MOD(ROW()-6,12)+2,0),0,IF('سجل الأصول'!$K$6:$K$100="القسط الثابت",'سجل الأصول'!$G$6:$G$100*MIN(MAX(0,(YEAR(DATE(2024+INT((ROW()-6)/12),MOD(ROW()-6,12)+2,0))-YEAR('سجل الأصول'!$I$6:$I$100))*12+MONTH(DATE(2024+INT((ROW()-6)/12),MOD(ROW()-6,12)+2,0))-MONTH('سجل الأصول'!$I$6:$I$100)),'سجل الأصول'!$J$6:$J$100*12)/('سجل الأصول'!$J$6:$J$100*12),IF('سجل الأصول'!$K$6:$K$100="القسط المتناقص",'سجل الأصول'!$E$6:$E$100*(1-(1-'سجل الأصول'!$L$6:$L$100/100)^MIN(MAX(0,YEAR(DATE(2024+INT((ROW()-6)/12),MOD(ROW()-6,12)+2,0))-YEAR('سجل الأصول'!$I$6:$I$100)),'سجل الأصول'!$J$6:$J$100)),IF('سجل الأصول'!$K$6:$K$100="وحدات الإنتاج",'سجل الأصول'!$G$6:$G$100*MIN(100,'سجل الأصول'!$L$6:$L$100*MAX(0,YEAR(DATE(2024+INT((ROW()-6)/12),MOD(ROW()-6,12)+2,0))-YEAR('سجل الأصول'!$I$6:$I$100)))/100,0)))))) -> 95000 | F11: =SUMPRODUCT(('سجل الأصول'!$D$6:$D$100="تجهيزات")*('سجل الأصول'!$N$6:$N$100<>"مهلك")*('سجل الأصول'!$E$6:$E$100-IF('سجل الأصول'!$I$6:$I$100>DATE(2024+INT((ROW()-6)/12),MOD(ROW()-6,12)+2,0),0,IF('سجل الأصول'!$K$6:$K$100="القسط الثابت",'سجل الأصول'!$G$6:$G$100*MIN(MAX(0,(YEAR(DATE(2024+INT((ROW()-6)/12),MOD(ROW()-6,12)+2,0))-YEAR('سجل الأصول'!$I$6:$I$100))*12+MONTH(DATE(2024+INT((ROW()-6)/12),MOD(ROW()-6,12)+2,0))-MONTH('سجل الأصول'!$I$6:$I$100)),'سجل الأصول'!$J$6:$J$100*12)/('سجل الأصول'!$J$6:$J$100*12),IF('سجل الأصول'!$K$6:$K$100="القسط المتناقص",'سجل الأصول'!$E$6:$E$100*(1-(1-'سجل الأصول'!$L$6:$L$100/100)^MIN(MAX(0,YEAR(DATE(2024+INT((ROW()-6)/12),MOD(ROW()-6,12)+2,0))-YEAR('سجل الأصول'!$I$6:$I$100)),'سجل الأصول'!$J$6:$J$100)),IF('سجل الأصول'!$K$6:$K$100="وحدات الإنتاج",'سجل الأصول'!$G$6:$G$100*MIN(100,'سجل الأصول'!$L$6:$L$100*MAX(0,YEAR(DATE(2024+INT((ROW()-6)/12),MOD(ROW()-6,12)+2,0))-YEAR('سجل الأصول'!$I$6:$I$100)))/100,0)))))) -> 65000 | G11: =SUMPRODUCT(('سجل الأصول'!$D$6:$D$100="مركبات")*('سجل الأصول'!$N$6:$N$100<>"مهلك")*('سجل الأصول'!$E$6:$E$100-IF('سجل الأصول'!$I$6:$I$100>DATE(2024+INT((ROW()-6)/12),MOD(ROW()-6,12)+2,0),0,IF('سجل الأصول'!$K$6:$K$100="القسط الثابت",'سجل الأصول'!$G$6:$G$100*MIN(MAX(0,(YEAR(DATE(2024+INT((ROW()-6)/12),MOD(ROW()-6,12)+2,0))-YEAR('سجل الأصول'!$I$6:$I$100))*12+MONTH(DATE(2024+INT((ROW()-6)/12),MOD(ROW()-6,12)+2,0))-MONTH('سجل الأصول'!$I$6:$I$100)),'سجل الأصول'!$J$6:$J$100*12)/('سجل الأصول'!$J$6:$J$100*12),IF('سجل الأصول'!$K$6:$K$100="القسط المتناقص",'سجل الأصول'!$E$6:$E$100*(1-(1-'سجل الأصول'!$L$6:$L$100/100)^MIN(MAX(0,YEAR(DATE(2024+INT((ROW()-6)/12),MOD(ROW()-6,12)+2,0))-YEAR('سجل الأصول'!$I$6:$I$100)),'سجل الأصول'!$J$6:$J$100)),IF('سجل الأصول'!$K$6:$K$100="وحدات الإنتاج",'سجل الأصول'!$G$6:$G$100*MIN(100,'سجل الأصول'!$L$6:$L$100*MAX(0,YEAR(DATE(2024+INT((ROW()-6)/12),MOD(ROW()-6,12)+2,0))-YEAR('سجل الأصول'!$I$6:$I$100)))/100,0)))))) -> 85000 | H11: =SUM(C11:G11) -> 431000
